Workbook

Sheet Dashboard Mensual
B1: =CONCATENATE("BIOWELLNESS — Dashboard de Gestión · ",Parámetros!C5) -> BIOWELLNESS — Dashboard de Gestión · Agosto 2026
B2: Resumen del mes para Andrés y socios · se actualiza solo
B4: INGRESOS WELLNESS (ARS) | D4: INGRESOS (USD) | F4: RESULTADO TOTAL (ARS) | H4: MARGEN | J4: MRR MEMBRESÍAS (USD) | L4: OCUPACIÓN PROM.
B5: =SUMIFS('Caja Diaria'!$F$4:$F$403,'Caja Diaria'!$B$4:$B$403,"Ingreso") -> 5836500 | D5: =SUMIFS('Caja Diaria'!$F$4:$F$403,'Caja Diaria'!$B$4:$B$403,"Ingreso")/Parámetros!$C$8 -> 3891 | F5: =C20 -> -6187250 | H5: =C21 -> -1.137197 | J5: ='Membresías & Combos'!$E$16 -> 13214 | L5: =IF(SUMPRODUCT(Parámetros!$E$15:$E$27)=0,0,SUMPRODUCT(COUNTIF(Sesiones!$B$4:$B$903,Parámetros!$B$15:$B$27))/SUMPRODUCT(Parámetros!$E$15:$E$27)) -> 0.0014814815
B8: Estado de Resultados del mes (para socios) | H8: Mix de ingresos por línea
B9: Concepto | C9: ARS | D9: USD | H9: Línea | I9: ARS | J9: % del total
B10: Membresías | C10: =SUMIFS('Caja Diaria'!$F$4:$F$403,'Caja Diaria'!$B$4:$B$403,"Ingreso",'Caja Diaria'!$C$4:$C$403,"Membresías") -> 2628000 | D10: =C10/Parámetros!$C$8 -> 1752 | H10: Membresías | I10: =SUMIFS('Caja Diaria'!$F$4:$F$403,'Caja Diaria'!$B$4:$B$403,"Ingreso",'Caja Diaria'!$C$4:$C$403,"Membresías") -> 2628000 | J10: =IF($I$15=0,0,I10/$I$15) -> 0.45026985
B11: Sueltas & Combos | C11: =SUMIFS('Caja Diaria'!$F$4:$F$403,'Caja Diaria'!$B$4:$B$403,"Ingreso",'Caja Diaria'!$C$4:$C$403,"Sueltas & Combos") -> 606000 | D11: =C11/Parámetros!$C$8 -> 404 | H11: Sueltas & Combos | I11: =SUMIFS('Caja Diaria'!$F$4:$F$403,'Caja Diaria'!$B$4:$B$403,"Ingreso",'Caja Diaria'!$C$4:$C$403,"Sueltas & Combos") -> 606000 | J11: =IF($I$15=0,0,I11/$I$15) -> 0.10382935
B12: Paquetes | C12: =SUMIFS('Caja Diaria'!$F$4:$F$403,'Caja Diaria'!$B$4:$B$403,"Ingreso",'Caja Diaria'!$C$4:$C$403,"Paquetes") -> 2227500 | D12: =C12/Parámetros!$C$8 -> 1485 | H12: Paquetes | I12: =SUMIFS('Caja Diaria'!$F$4:$F$403,'Caja Diaria'!$B$4:$B$403,"Ingreso",'Caja Diaria'!$C$4:$C$403,"Paquetes") -> 2227500 | J12: =IF($I$15=0,0,I12/$I$15) -> 0.38164996
B13: IV + Terapias Biológicas | C13: =SUMIFS('Caja Diaria'!$F$4:$F$403,'Caja Diaria'!$B$4:$B$403,"Ingreso",'Caja Diaria'!$C$4:$C$403,"IV + Terapias Biológicas") -> 375000 | D13: =C13/Parámetros!$C$8 -> 250 | H13: IV + Terapias Biológicas | I13: =SUMIFS('Caja Diaria'!$F$4:$F$403,'Caja Diaria'!$B$4:$B$403,"Ingreso",'Caja Diaria'!$C$4:$C$403,"IV + Terapias Biológicas") -> 375000 | J13: =IF($I$15=0,0,I13/$I$15) -> 0.064250835
B14: Otros | C14: =SUMIFS('Caja Diaria'!$F$4:$F$403,'Caja Diaria'!$B$4:$B$403,"Ingreso",'Caja Diaria'!$C$4:$C$403,"Otros") -> 0 | D14: =C14/Parámetros!$C$8 -> 0 | H14: Otros | I14: =SUMIFS('Caja Diaria'!$F$4:$F$403,'Caja Diaria'!$B$4:$B$403,"Ingreso",'Caja Diaria'!$C$4:$C$403,"Otros") -> 0 | J14: =IF($I$15=0,0,I14/$I$15) -> 0
B15: INGRESOS WELLNESS (cobrado) | C15: =SUMIFS('Caja Diaria'!$F$4:$F$403,'Caja Diaria'!$B$4:$B$403,"Ingreso") -> 5836500 | D15: =C15/Parámetros!$C$8 -> 3891 | H15: TOTAL | I15: =SUM(I10:I14) -> 5836500 | J15: =SUM(J10:J14) -> 1
B16: (–) Gastos operativos del mes | C16: =-'Gastos del Mes'!$C$21 -> -12398750 | D16: =C16/Parámetros!$C$8 -> -8265.8333
B17: (–) Egresos de caja chica | C17: =-SUMIFS('Caja Diaria'!$F$4:$F$403,'Caja Diaria'!$B$4:$B$403,"Egreso") -> -75000 | D17: =C17/Parámetros!$C$8 -> -50
B18: RESULTADO WELLNESS (EBITDA) | C18: =SUMIFS('Caja Diaria'!$F$4:$F$403,'Caja Diaria'!$B$4:$B$403,"Ingreso")-'Gastos del Mes'!$C$21-SUMIFS('Caja Diaria'!$F$4:$F$403,'Caja Diaria'!$B$4:$B$403,"Egreso") -> -6637250 | D18: =C18/Parámetros!$C$8 -> -4424.8333
B19: (+) Bar — resultado neto (manual) | C19: 450000 | D19: =C19/Parámetros!$C$8 -> 300
B20: RESULTADO TOTAL DEL NEGOCIO | C20: =C18+C19 -> -6187250 | D20: =C20/Parámetros!$C$8 -> -4124.8333
B21: Margen operativo (wellness) | C21: =IF(C15=0,0,C18/C15) -> -1.137197
B26: Utilización por recurso (mes)
B27: Recurso | C27: Sesiones | D27: % utilización
B28: HBOT Monoplaza | C28: =COUNTIF(Sesiones!$B$4:$B$903,B28) -> 2 | D28: =IF(Parámetros!$E$15=0,0,C28/Parámetros!$E$15) -> 0.0066666667
B29: HBOT Biplaza | C29: =COUNTIF(Sesiones!$B$4:$B$903,B29) -> 0 | D29: =IF(Parámetros!$E$16=0,0,C29/Parámetros!$E$16) -> 0
B30: HBOT Multiplaza | C30: =COUNTIF(Sesiones!$B$4:$B$903,B30) -> 1 | D30: =IF(Parámetros!$E$17=0,0,C30/Parámetros!$E$17) -> 0.0033333333
B31: IHHT 1 | C31: =COUNTIF(Sesiones!$B$4:$B$903,B31) -> 1 | D31: =IF(Parámetros!$E$18=0,0,C31/Parámetros!$E$18) -> 0.0016666667
B32: IHHT 2 | C32: =COUNTIF(Sesiones!$B$4:$B$903,B32) -> 1 | D32: =IF(Parámetros!$E$19=0,0,C32/Parámetros!$E$19) -> 0.0016666667
B33: Recovery Pro Gab 1 | C33: =COUNTIF(Sesiones!$B$4:$B$903,B33) -> 1 | D33: =IF(Parámetros!$E$20=0,0,C33/Parámetros!$E$20) -> 0.0033333333
B34: Recovery Pro Gab 2 | C34: =COUNTIF(Sesiones!$B$4:$B$903,B34) -> 0 | D34: =IF(Parámetros!$E$21=0,0,C34/Parámetros!$E$21) -> 0
B35: Red Light | C35: =COUNTIF(Sesiones!$B$4:$B$903,B35) -> 1 | D35: =IF(Parámetros!$E$22=0,0,C35/Parámetros!$E$22) -> 0.0016666667
B36: Compresión (IPC06) | C36: =COUNTIF(Sesiones!$B$4:$B$903,B36) -> 0 | D36: =IF(Parámetros!$E$23=0,0,C36/Parámetros!$E$23) -> 0
B37: Crio (COT03) | C37: =COUNTIF(Sesiones!$B$4:$B$903,B37) -> 0 | D37: =IF(Parámetros!$E$24=0,0,C37/Parámetros!$E$24) -> 0
B38: Camilla masajes | C38: =COUNTIF(Sesiones!$B$4:$B$903,B38) -> 0 | D38: =IF(Parámetros!$E$25=0,0,C38/Parámetros!$E$25) -> 0
B39: Consultorio médico | C39: =COUNTIF(Sesiones!$B$4:$B$903,B39) -> 0 | D39: =IF(Parámetros!$E$26=0,0,C39/Parámetros!$E$26) -> 0
B40: Sala TB / IV | C40: =COUNTIF(Sesiones!$B$4:$B$903,B40) -> 1 | D40: =IF(Parámetros!$E$27=0,0,C40/Parámetros!$E$27) -> 0.0033333333
B42: Distribución del resultado por socio | G42: Referencia: reparto bruto del resultado total. No descuenta reservas/CAPEX. Validar con Andrés.
B43: Socio | C43: % | D43: Parte (ARS)
B44: Andrés Aizenberg | C44: 0.53 | D44: =C44*$C20 -> -3279242.5
B45: Diego | C45: 0.24 | D45: =C45*$C20 -> -1484940
B46: Daniel Tognetti | C46: 0.09 | D46: =C46*$C20 -> -556852.5
B47: Evangelina Varela | C47: 0.06 | D47: =C47*$C20 -> -371235
B48: Julián Massetti | C48: 0.05 | D48: =C48*$C20 -> -309362.5
...

Sheet Parámetros
B1: BIOWELLNESS — Tablero de Gestión Mensual | J1: LISTAS (no tocar)
B2: Parámetros · editá solo las celdas en AZUL / fondo amarillo | J2: Membresías | K2: Efectivo | L2: Insumos menores | M2: Ingreso | N2: HBOT Monoplaza
J3: Sueltas & Combos | K3: Tarjeta débito | L3: Limpieza | M3: Egreso | N3: HBOT Biplaza
B4: General | J4: Paquetes | K4: Tarjeta crédito | L4: Viáticos | N4: HBOT Multiplaza
B5: Mes | C5: Agosto 2026 | J5: IV + Terapias Biológicas | K5: Transferencia | L5: Mantenimiento menor | N5: IHHT 1
B6: Año | C6: 2026 | J6: Otros | K6: MercadoPago | L6: Varios | N6: IHHT 2
B7: Mes (número) | C7: 8 | D7: 1=Ene ... 12=Dic | N7: Recovery Pro Gab 1
B8: Tipo de cambio (ARS por USD) | C8: 1500 | D8: Editable cada mes | N8: Recovery Pro Gab 2
B9: Días operativos del mes | C9: 25 | N9: Red Light
B10: Horas operativas por día | C10: 12 | D10: Ej. 9:00-21:00 | N10: Compresión (IPC06)
B11: Saldo inicial caja chica (ARS) | C11: 0 | D11: Efectivo físico al arrancar el mes | N11: Crio (COT03)
N12: Camilla masajes
B13: Recursos físicos y capacidad | D13: (Slots/día y capacidad se calculan solos) | N13: Consultorio médico
B14: Recurso | C14: Duración (min) | D14: Slots / día | E14: Capacidad mensual | N14: Sala TB / IV
B15: HBOT Monoplaza | C15: 60 | D15: =INT(($C$10*60)/C15) -> 12 | E15: =D15*$C$9 -> 300
B16: HBOT Biplaza | C16: 60 | D16: =INT(($C$10*60)/C16) -> 12 | E16: =D16*$C$9 -> 300
B17: HBOT Multiplaza | C17: 60 | D17: =INT(($C$10*60)/C17) -> 12 | E17: =D17*$C$9 -> 300
B18: IHHT 1 | C18: 30 | D18: =INT(($C$10*60)/C18) -> 24 | E18: =D18*$C$9 -> 600
B19: IHHT 2 | C19: 30 | D19: =INT(($C$10*60)/C19) -> 24 | E19: =D19*$C$9 -> 600
B20: Recovery Pro Gab 1 | C20: 60 | D20: =INT(($C$10*60)/C20) -> 12 | E20: =D20*$C$9 -> 300
B21: Recovery Pro Gab 2 | C21: 60 | D21: =INT(($C$10*60)/C21) -> 12 | E21: =D21*$C$9 -> 300
B22: Red Light | C22: 30 | D22: =INT(($C$10*60)/C22) -> 24 | E22: =D22*$C$9 -> 600
B23: Compresión (IPC06) | C23: 30 | D23: =INT(($C$10*60)/C23) -> 24 | E23: =D23*$C$9 -> 600
B24: Crio (COT03) | C24: 30 | D24: =INT(($C$10*60)/C24) -> 24 | E24: =D24*$C$9 -> 600
B25: Camilla masajes | C25: 60 | D25: =INT(($C$10*60)/C25) -> 12 | E25: =D25*$C$9 -> 300
B26: Consultorio médico | C26: 60 | D26: =INT(($C$10*60)/C26) -> 12 | E26: =D26*$C$9 -> 300
B27: Sala TB / IV | C27: 60 | D27: =INT(($C$10*60)/C27) -> 12 | E27: =D27*$C$9 -> 300
B28: Nota: Recovery Pro Gab 1 y 2 comparten 2 tumbonas Red Light (Regla R-07). Ajustá Slots/día si hace falta.

Sheet Caja Diaria
A1: Caja Diaria — ingresos cobrados y egresos de caja chica
A2: Una fila por movimiento de plata. El Bar NO va acá (es unidad aparte). USD se calcula solo.
A3: Fecha | B3: Tipo | C3: Línea / Categoría | D3: Detalle | E3: Método de pago | F3: Monto ARS | G3: Monto USD
A4: 46237 | B4: Ingreso | C4: Membresías | D4: PRIME Standard - J. Perez | E4: MercadoPago | F4: 2628000 | G4: =IF(F4="","",F4/Parámetros!$C$8) -> 1752
A5: 46237 | B5: Ingreso | C5: Sueltas & Combos | D5: BIO RECOVERY - M. Gomez | E5: Tarjeta crédito | F5: 438000 | G5: =IF(F5="","",F5/Parámetros!$C$8) -> 292
A6: 46237 | B6: Ingreso | C6: IV + Terapias Biológicas | D6: IV NAD+ - L. Ruiz | E6: Efectivo | F6: 375000 | G6: =IF(F6="","",F6/Parámetros!$C$8) -> 250
A7: 46237 | B7: Egreso | C7: Insumos menores | D7: Cánulas y guantes | E7: Efectivo | F7: 45000 | G7: =IF(F7="","",F7/Parámetros!$C$8) -> 30
A8: 46238 | B8: Ingreso | C8: Paquetes | D8: Paquete 10 HBOT - A. Diaz | E8: Tarjeta crédito | F8: 2227500 | G8: =IF(F8="","",F8/Parámetros!$C$8) -> 1485
A9: 46238 | B9: Ingreso | C9: Sueltas & Combos | D9: BIO ENERGY - S. Mora | E9: Efectivo | F9: 168000 | G9: =IF(F9="","",F9/Parámetros!$C$8) -> 112
A10: 46238 | B10: Egreso | C10: Limpieza | D10: Artículos de limpieza | E10: Efectivo | F10: 30000 | G10: =IF(F10="","",F10/Parámetros!$C$8) -> 20
G11: =IF(F11="","",F11/Parámetros!$C$8)
G12: =IF(F12="","",F12/Parámetros!$C$8)
G13: =IF(F13="","",F13/Parámetros!$C$8)
G14: =IF(F14="","",F14/Parámetros!$C$8)
G15: =IF(F15="","",F15/Parámetros!$C$8)
G16: =IF(F16="","",F16/Parámetros!$C$8)
G17: =IF(F17="","",F17/Parámetros!$C$8)
G18: =IF(F18="","",F18/Parámetros!$C$8)
G19: =IF(F19="","",F19/Parámetros!$C$8)
G20: =IF(F20="","",F20/Parámetros!$C$8)
G21: =IF(F21="","",F21/Parámetros!$C$8)
G22: =IF(F22="","",F22/Parámetros!$C$8)
... G403: =IF(F403="","",F403/Parámetros!$C$8)

Sheet Sesiones
A1: Sesiones realizadas — uso de recursos (ocupación)
A2: Una fila por sesión realizada (la pague socio o no). Mide ocupación, no plata.
A3: Fecha | B3: Recurso | C3: Servicio / Combo | D3: Ocupantes | E3: ¿Socio? | F3: Paciente
A4: 46237 | B4: HBOT Monoplaza | C4: BIO RECOVERY | D4: 1 | E4: No | F4: M. Gomez
A5: 46237 | B5: Recovery Pro Gab 1 | C5: BIO RECOVERY | D5: 1 | E5: No | F5: M. Gomez
A6: 46237 | B6: Sala TB / IV | C6: IV NAD+ | D6: 1 | E6: No | F6: L. Ruiz
A7: 46237 | B7: HBOT Monoplaza | C7: FOCUS Standard | D7: 1 | E7: Sí | F7: J. Perez
A8: 46237 | B8: IHHT 1 | C8: FOCUS Standard | D8: 1 | E8: Sí | F8: J. Perez
A9: 46238 | B9: HBOT Multiplaza | C9: Suelta | D9: 3 | E9: No | F9: Grupo corp.
A10: 46238 | B10: Red Light | C10: BIO ENERGY | D10: 1 | E10: No | F10: S. Mora
A11: 46238 | B11: IHHT 2 | C11: BIO ENERGY | D11: 1 | E11: No | F11: S. Mora

Sheet Resumen Diario
A1: Resumen Diario — cierre de caja y % de utilización por recurso
A2: Se llena solo. 'Saldo acum. mes' = lo que generó el negocio en el mes hasta ese día. 'Saldo efectivo caja' = efectivo físico real (entra cash, sale caja chica).
A3: Día | B3: Ingresos ARS | C3: Egresos ARS | D3: Saldo del día | E3: Saldo acum. mes | F3: Saldo efectivo caja | G3: Ingresos USD | H3: HBOT Monoplaza | I3: HBOT Biplaza | J3: HBOT Multiplaza | K3: IHHT 1 | L3: IHHT 2 | M3: Recovery Pro Gab 1 | N3: Recovery Pro Gab 2 | O3: Red Light | P3: Compresión (IPC06) | Q3: Crio (COT03) | R3: Camilla masajes | S3: Consultorio médico | T3: Sala TB / IV
A4: =DATE(Parámetros!$C$6,Parámetros!$C$7,1) -> 46235 | B4: =SUMIFS('Caja Diaria'!$F$4:$F$403,'Caja Diaria'!$B$4:$B$403,"Ingreso",'Caja Diaria'!$A$4:$A$403,$A4) -> 0 | C4: =SUMIFS('Caja Diaria'!$F$4:$F$403,'Caja Diaria'!$B$4:$B$403,"Egreso",'Caja Diaria'!$A$4:$A$403,$A4) -> 0 | D4: =B4-C4 -> 0 | E4: =D4 -> 0 | F4: =Parámetros!$C$11+SUMIFS('Caja Diaria'!$F$4:$F$403,'Caja Diaria'!$B$4:$B$403,"Ingreso",'Caja Diaria'!$E$4:$E$403,"Efectivo",'Caja Diaria'!$A$4:$A$403,$A4)-SUMIFS('Caja Diaria'!$F$4:$F$403,'Caja Diaria'!$B$4:$B$403,"Egreso",'Caja Diaria'!$E$4:$E$403,"Efectivo",'Caja Diaria'!$A$4:$A$403,$A4) -> 0 | G4: =B4/Parámetros!$C$8 -> 0 | H4: =IF(Parámetros!$D$15=0,0,COUNTIFS(Sesiones!$A$4:$A$903,$A4,Sesiones!$B$4:$B$903,Parámetros!$B$15)/Parámetros!$D$15) -> 0 | I4: =IF(Parámetros!$D$16=0,0,COUNTIFS(Sesiones!$A$4:$A$903,$A4,Sesiones!$B$4:$B$903,Parámetros!$B$16)/Parámetros!$D$16) -> 0 | J4: =IF(Parámetros!$D$17=0,0,COUNTIFS(Sesiones!$A$4:$A$903,$A4,Sesiones!$B$4:$B$903,Parámetros!$B$17)/Parámetros!$D$17) -> 0 | K4: =IF(Parámetros!$D$18=0,0,COUNTIFS(Sesiones!$A$4:$A$903,$A4,Sesiones!$B$4:$B$903,Parámetros!$B$18)/Parámetros!$D$18) -> 0 | L4: =IF(Parámetros!$D$19=0,0,COUNTIFS(Sesiones!$A$4:$A$903,$A4,Sesiones!$B$4:$B$903,Parámetros!$B$19)/Parámetros!$D$19) -> 0 | M4: =IF(Parámetros!$D$20=0,0,COUNTIFS(Sesiones!$A$4:$A$903,$A4,Sesiones!$B$4:$B$903,Parámetros!$B$20)/Parámetros!$D$20) -> 0 | N4: =IF(Parámetros!$D$21=0,0,COUNTIFS(Sesiones!$A$4:$A$903,$A4,Sesiones!$B$4:$B$903,Parámetros!$B$21)/Parámetros!$D$21) -> 0 | O4: =IF(Parámetros!$D$22=0,0,COUNTIFS(Sesiones!$A$4:$A$903,$A4,Sesiones!$B$4:$B$903,Parámetros!$B$22)/Parámetros!$D$22) -> 0 | P4: =IF(Parámetros!$D$23=0,0,COUNTIFS(Sesiones!$A$4:$A$903,$A4,Sesiones!$B$4:$B$903,Parámetros!$B$23)/Parámetros!$D$23) -> 0 | Q4: =IF(Parámetros!$D$24=0,0,COUNTIFS(Sesiones!$A$4:$A$903,$A4,Sesiones!$B$4:$B$903,Parámetros!$B$24)/Parámetros!$D$24) -> 0 | R4: =IF(Parámetros!$D$25=0,0,COUNTIFS(Sesiones!$A$4:$A$903,$A4,Sesiones!$B$4:$B$903,Parámetros!$B$25)/Parámetros!$D$25) -> 0 | S4: =IF(Parámetros!$D$26=0,0,COUNTIFS(Sesiones!$A$4:$A$903,$A4,Sesiones!$B$4:$B$903,Parámetros!$B$26)/Parámetros!$D$26) -> 0 | T4: =IF(Parámetros!$D$27=0,0,COUNTIFS(Sesiones!$A$4:$A$903,$A4,Sesiones!$B$4:$B$903,Parámetros!$B$27)/Parámetros!$D$27) -> 0
A5: =DATE(Parámetros!$C$6,Parámetros!$C$7,2) -> 46236 | B5: =SUMIFS('Caja Diaria'!$F$4:$F$403,'Caja Diaria'!$B$4:$B$403,"Ingreso",'Caja Diaria'!$A$4:$A$403,$A5) -> 0 | C5: =SUMIFS('Caja Diaria'!$F$4:$F$403,'Caja Diaria'!$B$4:$B$403,"Egreso",'Caja Diaria'!$A$4:$A$403,$A5) -> 0 | D5: =B5-C5 -> 0 | E5: =E4+D5 -> 0 | F5: =F4+SUMIFS('Caja Diaria'!$F$4:$F$403,'Caja Diaria'!$B$4:$B$403,"Ingreso",'Caja Diaria'!$E$4:$E$403,"Efectivo",'Caja Diaria'!$A$4:$A$403,$A5)-SUMIFS('Caja Diaria'!$F$4:$F$403,'Caja Diaria'!$B$4:$B$403,"Egreso",'Caja Diaria'!$E$4:$E$403,"Efectivo",'Caja Diaria'!$A$4:$A$403,$A5) -> 0 | G5: =B5/Parámetros!$C$8 -> 0 | H5: =IF(Parámetros!$D$15=0,0,COUNTIFS(Sesiones!$A$4:$A$903,$A5,Sesiones!$B$4:$B$903,Parámetros!$B$15)/Parámetros!$D$15) -> 0 | I5: =IF(Parámetros!$D$16=0,0,COUNTIFS(Sesiones!$A$4:$A$903,$A5,Sesiones!$B$4:$B$903,Parámetros!$B$16)/Parámetros!$D$16) -> 0 | J5: =IF(Parámetros!$D$17=0,0,COUNTIFS(Sesiones!$A$4:$A$903,$A5,Sesiones!$B$4:$B$903,Parámetros!$B$17)/Parámetros!$D$17) -> 0 | K5: =IF(Parámetros!$D$18=0,0,COUNTIFS(Sesiones!$A$4:$A$903,$A5,Sesiones!$B$4:$B$903,Parámetros!$B$18)/Parámetros!$D$18) -> 0 | L5: =IF(Parámetros!$D$19=0,0,COUNTIFS(Sesiones!$A$4:$A$903,$A5,Sesiones!$B$4:$B$903,Parámetros!$B$19)/Parámetros!$D$19) -> 0 | M5: =IF(Parámetros!$D$20=0,0,COUNTIFS(Sesiones!$A$4:$A$903,$A5,Sesiones!$B$4:$B$903,Parámetros!$B$20)/Parámetros!$D$20) -> 0 | N5: =IF(Parámetros!$D$21=0,0,COUNTIFS(Sesiones!$A$4:$A$903,$A5,Sesiones!$B$4:$B$903,Parámetros!$B$21)/Parámetros!$D$21) -> 0 | O5: =IF(Parámetros!$D$22=0,0,COUNTIFS(Sesiones!$A$4:$A$903,$A5,Sesiones!$B$4:$B$903,Parámetros!$B$22)/Parámetros!$D$22) -> 0 | P5: =IF(Parámetros!$D$23=0,0,COUNTIFS(Sesiones!$A$4:$A$903,$A5,Sesiones!$B$4:$B$903,Parámetros!$B$23)/Parámetros!$D$23) -> 0 | Q5: =IF(Parámetros!$D$24=0,0,COUNTIFS(Sesiones!$A$4:$A$903,$A5,Sesiones!$B$4:$B$903,Parámetros!$B$24)/Parámetros!$D$24) -> 0 | R5: =IF(Parámetros!$D$25=0,0,COUNTIFS(Sesiones!$A$4:$A$903,$A5,Sesiones!$B$4:$B$903,Parámetros!$B$25)/Parámetros!$D$25) -> 0 | S5: =IF(Parámetros!$D$26=0,0,COUNTIFS(Sesiones!$A$4:$A$903,$A5,Sesiones!$B$4:$B$903,Parámetros!$B$26)/Parámetros!$D$26) -> 0 | T5: =IF(Parámetros!$D$27=0,0,COUNTIFS(Sesiones!$A$4:$A$903,$A5,Sesiones!$B$4:$B$903,Parámetros!$B$27)/Parámetros!$D$27) -> 0
A6: =DATE(Parámetros!$C$6,Parámetros!$C$7,3) -> 46237 | B6: =SUMIFS('Caja Diaria'!$F$4:$F$403,'Caja Diaria'!$B$4:$B$403,"Ingreso",'Caja Diaria'!$A$4:$A$403,$A6) -> 3441000 | C6: =SUMIFS('Caja Diaria'!$F$4:$F$403,'Caja Diaria'!$B$4:$B$403,"Egreso",'Caja Diaria'!$A$4:$A$403,$A6) -> 45000 | D6: =B6-C6 -> 3396000 | E6: =E5+D6 -> 3396000 | F6: =F5+SUMIFS('Caja Diaria'!$F$4:$F$403,'Caja Diaria'!$B$4:$B$403,"Ingreso",'Caja Diaria'!$E$4:$E$403,"Efectivo",'Caja Diaria'!$A$4:$A$403,$A6)-SUMIFS('Caja Diaria'!$F$4:$F$403,'Caja Diaria'!$B$4:$B$403,"Egreso",'Caja Diaria'!$E$4:$E$403,"Efectivo",'Caja Diaria'!$A$4:$A$403,$A6) -> 330000 | G6: =B6/Parámetros!$C$8 -> 2294 | H6: =IF(Parámetros!$D$15=0,0,COUNTIFS(Sesiones!$A$4:$A$903,$A6,Sesiones!$B$4:$B$903,Parámetros!$B$15)/Parámetros!$D$15) -> 0.16666667 | I6: =IF(Parámetros!$D$16=0,0,COUNTIFS(Sesiones!$A$4:$A$903,$A6,Sesiones!$B$4:$B$903,Parámetros!$B$16)/Parámetros!$D$16) -> 0 | J6: =IF(Parámetros!$D$17=0,0,COUNTIFS(Sesiones!$A$4:$A$903,$A6,Sesiones!$B$4:$B$903,Parámetros!$B$17)/Parámetros!$D$17) -> 0 | K6: =IF(Parámetros!$D$18=0,0,COUNTIFS(Sesiones!$A$4:$A$903,$A6,Sesiones!$B$4:$B$903,Parámetros!$B$18)/Parámetros!$D$18) -> 0.041666667 | L6: =IF(Parámetros!$D$19=0,0,COUNTIFS(Sesiones!$A$4:$A$903,$A6,Sesiones!$B$4:$B$903,Parámetros!$B$19)/Parámetros!$D$19) -> 0 | M6: =IF(Parámetros!$D$20=0,0,COUNTIFS(Sesiones!$A$4:$A$903,$A6,Sesiones!$B$4:$B$903,Parámetros!$B$20)/Parámetros!$D$20) -> 0.083333333 | N6: =IF(Parámetros!$D$21=0,0,COUNTIFS(Sesiones!$A$4:$A$903,$A6,Sesiones!$B$4:$B$903,Parámetros!$B$21)/Parámetros!$D$21) -> 0 | O6: =IF(Parámetros!$D$22=0,0,COUNTIFS(Sesiones!$A$4:$A$903,$A6,Sesiones!$B$4:$B$903,Parámetros!$B$22)/Parámetros!$D$22) -> 0 | P6: =IF(Parámetros!$D$23=0,0,COUNTIFS(Sesiones!$A$4:$A$903,$A6,Sesiones!$B$4:$B$903,Parámetros!$B$23)/Parámetros!$D$23) -> 0 | Q6: =IF(Parámetros!$D$24=0,0,COUNTIFS(Sesiones!$A$4:$A$903,$A6,Sesiones!$B$4:$B$903,Parámetros!$B$24)/Parámetros!$D$24) -> 0 | R6: =IF(Parámetros!$D$25=0,0,COUNTIFS(Sesiones!$A$4:$A$903,$A6,Sesiones!$B$4:$B$903,Parámetros!$B$25)/Parámetros!$D$25) -> 0 | S6: =IF(Parámetros!$D$26=0,0,COUNTIFS(Sesiones!$A$4:$A$903,$A6,Sesiones!$B$4:$B$903,Parámetros!$B$26)/Parámetros!$D$26) -> 0 | T6: =IF(Parámetros!$D$27=0,0,COUNTIFS(Sesiones!$A$4:$A$903,$A6,Sesiones!$B$4:$B$903,Parámetros!$B$27)/Parámetros!$D$27) -> 0.083333333
A7: =DATE(Parámetros!$C$6,Parámetros!$C$7,4) -> 46238 | B7: =SUMIFS('Caja Diaria'!$F$4:$F$403,'Caja Diaria'!$B$4:$B$403,"Ingreso",'Caja Diaria'!$A$4:$A$403,$A7) -> 2395500 | C7: =SUMIFS('Caja Diaria'!$F$4:$F$403,'Caja Diaria'!$B$4:$B$403,"Egreso",'Caja Diaria'!$A$4:$A$403,$A7) -> 30000 | D7: =B7-C7 -> 2365500 | E7: =E6+D7 -> 5761500 | F7: =F6+SUMIFS('Caja Diaria'!$F$4:$F$403,'Caja Diaria'!$B$4:$B$403,"Ingreso",'Caja Diaria'!$E$4:$E$403,"Efectivo",'Caja Diaria'!$A$4:$A$403,$A7)-SUMIFS('Caja Diaria'!$F$4:$F$403,'Caja Diaria'!$B$4:$B$403,"Egreso",'Caja Diaria'!$E$4:$E$403,"Efectivo",'Caja Diaria'!$A$4:$A$403,$A7) -> 468000 | G7: =B7/Parámetros!$C$8 -> 1597 | H7: =IF(Parámetros!$D$15=0,0,COUNTIFS(Sesiones!$A$4:$A$903,$A7,Sesiones!$B$4:$B$903,Parámetros!$B$15)/Parámetros!$D$15) -> 0 | I7: =IF(Parámetros!$D$16=0,0,COUNTIFS(Sesiones!$A$4:$A$903,$A7,Sesiones!$B$4:$B$903,Parámetros!$B$16)/Parámetros!$D$16) -> 0 | J7: =IF(Parámetros!$D$17=0,0,COUNTIFS(Sesiones!$A$4:$A$903,$A7,Sesiones!$B$4:$B$903,Parámetros!$B$17)/Parámetros!$D$17) -> 0.083333333 | K7: =IF(Parámetros!$D$18=0,0,COUNTIFS(Sesiones!$A$4:$A$903,$A7,Sesiones!$B$4:$B$903,Parámetros!$B$18)/Parámetros!$D$18) -> 0 | L7: =IF(Parámetros!$D$19=0,0,COUNTIFS(Sesiones!$A$4:$A$903,$A7,Sesiones!$B$4:$B$903,Parámetros!$B$19)/Parámetros!$D$19) -> 0.041666667 | M7: =IF(Parámetros!$D$20=0,0,COUNTIFS(Sesiones!$A$4:$A$903,$A7,Sesiones!$B$4:$B$903,Parámetros!$B$20)/Parámetros!$D$20) -> 0 | N7: =IF(Parámetros!$D$21=0,0,COUNTIFS(Sesiones!$A$4:$A$903,$A7,Sesiones!$B$4:$B$903,Parámetros!$B$21)/Parámetros!$D$21) -> 0 | O7: =IF(Parámetros!$D$22=0,0,COUNTIFS(Sesiones!$A$4:$A$903,$A7,Sesiones!$B$4:$B$903,Parámetros!$B$22)/Parámetros!$D$22) -> 0.041666667 | P7: =IF(Parámetros!$D$23=0,0,COUNTIFS(Sesiones!$A$4:$A$903,$A7,Sesiones!$B$4:$B$903,Parámetros!$B$23)/Parámetros!$D$23) -> 0 | Q7: =IF(Parámetros!$D$24=0,0,COUNTIFS(Sesiones!$A$4:$A$903,$A7,Sesiones!$B$4:$B$903,Parámetros!$B$24)/Parámetros!$D$24) -> 0 | R7: =IF(Parámetros!$D$25=0,0,COUNTIFS(Sesiones!$A$4:$A$903,$A7,Sesiones!$B$4:$B$903,Parámetros!$B$25)/Parámetros!$D$25) -> 0 | S7: =IF(Parámetros!$D$26=0,0,COUNTIFS(Sesiones!$A$4:$A$903,$A7,Sesiones!$B$4:$B$903,Parámetros!$B$26)/Parámetros!$D$26) -> 0 | T7: =IF(Parámetros!$D$27=0,0,COUNTIFS(Sesiones!$A$4:$A$903,$A7,Sesiones!$B$4:$B$903,Parámetros!$B$27)/Parámetros!$D$27) -> 0
A8: =DATE(Parámetros!$C$6,Parámetros!$C$7,5) -> 46239 | B8: =SUMIFS('Caja Diaria'!$F$4:$F$403,'Caja Diaria'!$B$4:$B$403,"Ingreso",'Caja Diaria'!$A$4:$A$403,$A8) -> 0 | C8: =SUMIFS('Caja Diaria'!$F$4:$F$403,'Caja Diaria'!$B$4:$B$403,"Egreso",'Caja Diaria'!$A$4:$A$403,$A8) -> 0 | D8: =B8-C8 -> 0 | E8: =E7+D8 -> 5761500 | F8: =F7+SUMIFS('Caja Diaria'!$F$4:$F$403,'Caja Diaria'!$B$4:$B$403,"Ingreso",'Caja Diaria'!$E$4:$E$403,"Efectivo",'Caja Diaria'!$A$4:$A$403,$A8)-SUMIFS('Caja Diaria'!$F$4:$F$403,'Caja Diaria'!$B$4:$B$403,"Egreso",'Caja Diaria'!$E$4:$E$403,"Efectivo",'Caja Diaria'!$A$4:$A$403,$A8) -> 468000 | G8: =B8/Parámetros!$C$8 -> 0 | H8: =IF(Parámetros!$D$15=0,0,COUNTIFS(Sesiones!$A$4:$A$903,$A8,Sesiones!$B$4:$B$903,Parámetros!$B$15)/Parámetros!$D$15) -> 0 | I8: =IF(Parámetros!$D$16=0,0,COUNTIFS(Sesiones!$A$4:$A$903,$A8,Sesiones!$B$4:$B$903,Parámetros!$B$16)/Parámetros!$D$16) -> 0 | J8: =IF(Parámetros!$D$17=0,0,COUNTIFS(Sesiones!$A$4:$A$903,$A8,Sesiones!$B$4:$B$903,Parámetros!$B$17)/Parámetros!$D$17) -> 0 | K8: =IF(Parámetros!$D$18=0,0,COUNTIFS(Sesiones!$A$4:$A$903,$A8,Sesiones!$B$4:$B$903,Parámetros!$B$18)/Parámetros!$D$18) -> 0 | L8: =IF(Parámetros!$D$19=0,0,COUNTIFS(Sesiones!$A$4:$A$903,$A8,Sesiones!$B$4:$B$903,Parámetros!$B$19)/Parámetros!$D$19) -> 0 | M8: =IF(Parámetros!$D$20=0,0,COUNTIFS(Sesiones!$A$4:$A$903,$A8,Sesiones!$B$4:$B$903,Parámetros!$B$20)/Parámetros!$D$20) -> 0 | N8: =IF(Parámetros!$D$21=0,0,COUNTIFS(Sesiones!$A$4:$A$903,$A8,Sesiones!$B$4:$B$903,Parámetros!$B$21)/Parámetros!$D$21) -> 0 | O8: =IF(Parámetros!$D$22=0,0,COUNTIFS(Sesiones!$A$4:$A$903,$A8,Sesiones!$B$4:$B$903,Parámetros!$B$22)/Parámetros!$D$22) -> 0 | P8: =IF(Parámetros!$D$23=0,0,COUNTIFS(Sesiones!$A$4:$A$903,$A8,Sesiones!$B$4:$B$903,Parámetros!$B$23)/Parámetros!$D$23) -> 0 | Q8: =IF(Parámetros!$D$24=0,0,COUNTIFS(Sesiones!$A$4:$A$903,$A8,Sesiones!$B$4:$B$903,Parámetros!$B$24)/Parámetros!$D$24) -> 0 | R8: =IF(Parámetros!$D$25=0,0,COUNTIFS(Sesiones!$A$4:$A$903,$A8,Sesiones!$B$4:$B$903,Parámetros!$B$25)/Parámetros!$D$25) -> 0 | S8: =IF(Parámetros!$D$26=0,0,COUNTIFS(Sesiones!$A$4:$A$903,$A8,Sesiones!$B$4:$B$903,Parámetros!$B$26)/Parámetros!$D$26) -> 0 | T8: =IF(Parámetros!$D$27=0,0,COUNTIFS(Sesiones!$A$4:$A$903,$A8,Sesiones!$B$4:$B$903,Parámetros!$B$27)/Parámetros!$D$27) -> 0
A9: =DATE(Parámetros!$C$6,Parámetros!$C$7,6) -> 46240 | B9: =SUMIFS('Caja Diaria'!$F$4:$F$403,'Caja Diaria'!$B$4:$B$403,"Ingreso",'Caja Diaria'!$A$4:$A$403,$A9) -> 0 | C9: =SUMIFS('Caja Diaria'!$F$4:$F$403,'Caja Diaria'!$B$4:$B$403,"Egreso",'Caja Diaria'!$A$4:$A$403,$A9) -> 0 | D9: =B9-C9 -> 0 | E9: =E8+D9 -> 5761500 | F9: =F8+SUMIFS('Caja Diaria'!$F$4:$F$403,'Caja Diaria'!$B$4:$B$403,"Ingreso",'Caja Diaria'!$E$4:$E$403,"Efectivo",'Caja Diaria'!$A$4:$A$403,$A9)-SUMIFS('Caja Diaria'!$F$4:$F$403,'Caja Diaria'!$B$4:$B$403,"Egreso",'Caja Diaria'!$E$4:$E$403,"Efectivo",'Caja Diaria'!$A$4:$A$403,$A9) -> 468000 | G9: =B9/Parámetros!$C$8 -> 0 | H9: =IF(Parámetros!$D$15=0,0,COUNTIFS(Sesiones!$A$4:$A$903,$A9,Sesiones!$B$4:$B$903,Parámetros!$B$15)/Parámetros!$D$15) -> 0 | I9: =IF(Parámetros!$D$16=0,0,COUNTIFS(Sesiones!$A$4:$A$903,$A9,Sesiones!$B$4:$B$903,Parámetros!$B$16)/Parámetros!$D$16) -> 0 | J9: =IF(Parámetros!$D$17=0,0,COUNTIFS(Sesiones!$A$4:$A$903,$A9,Sesiones!$B$4:$B$903,Parámetros!$B$17)/Parámetros!$D$17) -> 0 | K9: =IF(Parámetros!$D$18=0,0,COUNTIFS(Sesiones!$A$4:$A$903,$A9,Sesiones!$B$4:$B$903,Parámetros!$B$18)/Parámetros!$D$18) -> 0 | L9: =IF(Parámetros!$D$19=0,0,COUNTIFS(Sesiones!$A$4:$A$903,$A9,Sesiones!$B$4:$B$903,Parámetros!$B$19)/Parámetros!$D$19) -> 0 | M9: =IF(Parámetros!$D$20=0,0,COUNTIFS(Sesiones!$A$4:$A$903,$A9,Sesiones!$B$4:$B$903,Parámetros!$B$20)/Parámetros!$D$20) -> 0 | N9: =IF(Parámetros!$D$21=0,0,COUNTIFS(Sesiones!$A$4:$A$903,$A9,Sesiones!$B$4:$B$903,Parámetros!$B$21)/Parámetros!$D$21) -> 0 | O9: =IF(Parámetros!$D$22=0,0,COUNTIFS(Sesiones!$A$4:$A$903,$A9,Sesiones!$B$4:$B$903,Parámetros!$B$22)/Parámetros!$D$22) -> 0 | P9: =IF(Parámetros!$D$23=0,0,COUNTIFS(Sesiones!$A$4:$A$903,$A9,Sesiones!$B$4:$B$903,Parámetros!$B$23)/Parámetros!$D$23) -> 0 | Q9: =IF(Parámetros!$D$24=0,0,COUNTIFS(Sesiones!$A$4:$A$903,$A9,Sesiones!$B$4:$B$903,Parámetros!$B$24)/Parámetros!$D$24) -> 0 | R9: =IF(Parámetros!$D$25=0,0,COUNTIFS(Sesiones!$A$4:$A$903,$A9,Sesiones!$B$4:$B$903,Parámetros!$B$25)/Parámetros!$D$25) -> 0 | S9: =IF(Parámetros!$D$26=0,0,COUNTIFS(Sesiones!$A$4:$A$903,$A9,Sesiones!$B$4:$B$903,Parámetros!$B$26)/Parámetros!$D$26) -> 0 | T9: =IF(Parámetros!$D$27=0,0,COUNTIFS(Sesiones!$A$4:$A$903,$A9,Sesiones!$B$4:$B$903,Parámetros!$B$27)/Parámetros!$D$27) -> 0
A10: =DATE(Parámetros!$C$6,Parámetros!$C$7,7) -> 46241 | B10: =SUMIFS('Caja Diaria'!$F$4:$F$403,'Caja Diaria'!$B$4:$B$403,"Ingreso",'Caja Diaria'!$A$4:$A$403,$A10) -> 0 | C10: =SUMIFS('Caja Diaria'!$F$4:$F$403,'Caja Diaria'!$B$4:$B$403,"Egreso",'Caja Diaria'!$A$4:$A$403,$A10) -> 0 | D10: =B10-C10 -> 0 | E10: =E9+D10 -> 5761500 | F10: =F9+SUMIFS('Caja Diaria'!$F$4:$F$403,'Caja Diaria'!$B$4:$B$403,"Ingreso",'Caja Diaria'!$E$4:$E$403,"Efectivo",'Caja Diaria'!$A$4:$A$403,$A10)-SUMIFS('Caja Diaria'!$F$4:$F$403,'Caja Diaria'!$B$4:$B$403,"Egreso",'Caja Diaria'!$E$4:$E$403,"Efectivo",'Caja Diaria'!$A$4:$A$403,$A10) -> 468000 | G10: =B10/Parámetros!$C$8 -> 0 | H10: =IF(Parámetros!$D$15=0,0,COUNTIFS(Sesiones!$A$4:$A$903,$A10,Sesiones!$B$4:$B$903,Parámetros!$B$15)/Parámetros!$D$15) -> 0 | I10: =IF(Parámetros!$D$16=0,0,COUNTIFS(Sesiones!$A$4:$A$903,$A10,Sesiones!$B$4:$B$903,Parámetros!$B$16)/Parámetros!$D$16) -> 0 | J10: =IF(Parámetros!$D$17=0,0,COUNTIFS(Sesiones!$A$4:$A$903,$A10,Sesiones!$B$4:$B$903,Parámetros!$B$17)/Parámetros!$D$17) -> 0 | K10: =IF(Parámetros!$D$18=0,0,COUNTIFS(Sesiones!$A$4:$A$903,$A10,Sesiones!$B$4:$B$903,Parámetros!$B$18)/Parámetros!$D$18) -> 0 | L10: =IF(Parámetros!$D$19=0,0,COUNTIFS(Sesiones!$A$4:$A$903,$A10,Sesiones!$B$4:$B$903,Parámetros!$B$19)/Parámetros!$D$19) -> 0 | M10: =IF(Parámetros!$D$20=0,0,COUNTIFS(Sesiones!$A$4:$A$903,$A10,Sesiones!$B$4:$B$903,Parámetros!$B$20)/Parámetros!$D$20) -> 0 | N10: =IF(Parámetros!$D$21=0,0,COUNTIFS(Sesiones!$A$4:$A$903,$A10,Sesiones!$B$4:$B$903,Parámetros!$B$21)/Parámetros!$D$21) -> 0 | O10: =IF(Parámetros!$D$22=0,0,COUNTIFS(Sesiones!$A$4:$A$903,$A10,Sesiones!$B$4:$B$903,Parámetros!$B$22)/Parámetros!$D$22) -> 0 | P10: =IF(Parámetros!$D$23=0,0,COUNTIFS(Sesiones!$A$4:$A$903,$A10,Sesiones!$B$4:$B$903,Parámetros!$B$23)/Parámetros!$D$23) -> 0 | Q10: =IF(Parámetros!$D$24=0,0,COUNTIFS(Sesiones!$A$4:$A$903,$A10,Sesiones!$B$4:$B$903,Parámetros!$B$24)/Parámetros!$D$24) -> 0 | R10: =IF(Parámetros!$D$25=0,0,COUNTIFS(Sesiones!$A$4:$A$903,$A10,Sesiones!$B$4:$B$903,Parámetros!$B$25)/Parámetros!$D$25) -> 0 | S10: =IF(Parámetros!$D$26=0,0,COUNTIFS(Sesiones!$A$4:$A$903,$A10,Sesiones!$B$4:$B$903,Parámetros!$B$26)/Parámetros!$D$26) -> 0 | T10: =IF(Parámetros!$D$27=0,0,COUNTIFS(Sesiones!$A$4:$A$903,$A10,Sesiones!$B$4:$B$903,Parámetros!$B$27)/Parámetros!$D$27) -> 0
A11: =DATE(Parámetros!$C$6,Parámetros!$C$7,8) -> 46242 | B11: =SUMIFS('Caja Diaria'!$F$4:$F$403,'Caja Diaria'!$B$4:$B$403,"Ingreso",'Caja Diaria'!$A$4:$A$403,$A11) -> 0 | C11: =SUMIFS('Caja Diaria'!$F$4:$F$403,'Caja Diaria'!$B$4:$B$403,"Egreso",'Caja Diaria'!$A$4:$A$403,$A11) -> 0 | D11: =B11-C11 -> 0 | E11: =E10+D11 -> 5761500 | F11: =F10+SUMIFS('Caja Diaria'!$F$4:$F$403,'Caja Diaria'!$B$4:$B$403,"Ingreso",'Caja Diaria'!$E$4:$E$403,"Efectivo",'Caja Diaria'!$A$4:$A$403,$A11)-SUMIFS('Caja Diaria'!$F$4:$F$403,'Caja Diaria'!$B$4:$B$403,"Egreso",'Caja Diaria'!$E$4:$E$403,"Efectivo",'Caja Diaria'!$A$4:$A$403,$A11) -> 468000 | G11: =B11/Parámetros!$C$8 -> 0 | H11: =IF(Parámetros!$D$15=0,0,COUNTIFS(Sesiones!$A$4:$A$903,$A11,Sesiones!$B$4:$B$903,Parámetros!$B$15)/Parámetros!$D$15) -> 0 | I11: =IF(Parámetros!$D$16=0,0,COUNTIFS(Sesiones!$A$4:$A$903,$A11,Sesiones!$B$4:$B$903,Parámetros!$B$16)/Parámetros!$D$16) -> 0 | J11: =IF(Parámetros!$D$17=0,0,COUNTIFS(Sesiones!$A$4:$A$903,$A11,Sesiones!$B$4:$B$903,Parámetros!$B$17)/Parámetros!$D$17) -> 0 | K11: =IF(Parámetros!$D$18=0,0,COUNTIFS(Sesiones!$A$4:$A$903,$A11,Sesiones!$B$4:$B$903,Parámetros!$B$18)/Parámetros!$D$18) -> 0 | L11: =IF(Parámetros!$D$19=0,0,COUNTIFS(Sesiones!$A$4:$A$903,$A11,Sesiones!$B$4:$B$903,Parámetros!$B$19)/Parámetros!$D$19) -> 0 | M11: =IF(Parámetros!$D$20=0,0,COUNTIFS(Sesiones!$A$4:$A$903,$A11,Sesiones!$B$4:$B$903,Parámetros!$B$20)/Parámetros!$D$20) -> 0 | N11: =IF(Parámetros!$D$21=0,0,COUNTIFS(Sesiones!$A$4:$A$903,$A11,Sesiones!$B$4:$B$903,Parámetros!$B$21)/Parámetros!$D$21) -> 0 | O11: =IF(Parámetros!$D$22=0,0,COUNTIFS(Sesiones!$A$4:$A$903,$A11,Sesiones!$B$4:$B$903,Parámetros!$B$22)/Parámetros!$D$22) -> 0 | P11: =IF(Parámetros!$D$23=0,0,COUNTIFS(Sesiones!$A$4:$A$903,$A11,Sesiones!$B$4:$B$903,Parámetros!$B$23)/Parámetros!$D$23) -> 0 | Q11: =IF(Parámetros!$D$24=0,0,COUNTIFS(Sesiones!$A$4:$A$903,$A11,Sesiones!$B$4:$B$903,Parámetros!$B$24)/Parámetros!$D$24) -> 0 | R11: =IF(Parámetros!$D$25=0,0,COUNTIFS(Sesiones!$A$4:$A$903,$A11,Sesiones!$B$4:$B$903,Parámetros!$B$25)/Parámetros!$D$25) -> 0 | S11: =IF(Parámetros!$D$26=0,0,COUNTIFS(Sesiones!$A$4:$A$903,$A11,Sesiones!$B$4:$B$903,Parámetros!$B$26)/Parámetros!$D$26) -> 0 | T11: =IF(Parámetros!$D$27=0,0,COUNTIFS(Sesiones!$A$4:$A$903,$A11,Sesiones!$B$4:$B$903,Parámetros!$B$27)/Parámetros!$D$27) -> 0
A12: =DATE(Parámetros!$C$6,Parámetros!$C$7,9) -> 46243 | B12: =SUMIFS('Caja Diaria'!$F$4:$F$403,'Caja Diaria'!$B$4:$B$403,"Ingreso",'Caja Diaria'!$A$4:$A$403,$A12) -> 0 | C12: =SUMIFS('Caja Diaria'!$F$4:$F$403,'Caja Diaria'!$B$4:$B$403,"Egreso",'Caja Diaria'!$A$4:$A$403,$A12) -> 0 | D12: =B12-C12 -> 0 | E12: =E11+D12 -> 5761500 | F12: =F11+SUMIFS('Caja Diaria'!$F$4:$F$403,'Caja Diaria'!$B$4:$B$403,"Ingreso",'Caja Diaria'!$E$4:$E$403,"Efectivo",'Caja Diaria'!$A$4:$A$403,$A12)-SUMIFS('Caja Diaria'!$F$4:$F$403,'Caja Diaria'!$B$4:$B$403,"Egreso",'Caja Diaria'!$E$4:$E$403,"Efectivo",'Caja Diaria'!$A$4:$A$403,$A12) -> 468000 | G12: =B12/Parámetros!$C$8 -> 0 | H12: =IF(Parámetros!$D$15=0,0,COUNTIFS(Sesiones!$A$4:$A$903,$A12,Sesiones!$B$4:$B$903,Parámetros!$B$15)/Parámetros!$D$15) -> 0 | I12: =IF(Parámetros!$D$16=0,0,COUNTIFS(Sesiones!$A$4:$A$903,$A12,Sesiones!$B$4:$B$903,Parámetros!$B$16)/Parámetros!$D$16) -> 0 | J12: =IF(Parámetros!$D$17=0,0,COUNTIFS(Sesiones!$A$4:$A$903,$A12,Sesiones!$B$4:$B$903,Parámetros!$B$17)/Parámetros!$D$17) -> 0 | K12: =IF(Parámetros!$D$18=0,0,COUNTIFS(Sesiones!$A$4:$A$903,$A12,Sesiones!$B$4:$B$903,Parámetros!$B$18)/Parámetros!$D$18) -> 0 | L12: =IF(Parámetros!$D$19=0,0,COUNTIFS(Sesiones!$A$4:$A$903,$A12,Sesiones!$B$4:$B$903,Parámetros!$B$19)/Parámetros!$D$19) -> 0 | M12: =IF(Parámetros!$D$20=0,0,COUNTIFS(Sesiones!$A$4:$A$903,$A12,Sesiones!$B$4:$B$903,Parámetros!$B$20)/Parámetros!$D$20) -> 0 | N12: =IF(Parámetros!$D$21=0,0,COUNTIFS(Sesiones!$A$4:$A$903,$A12,Sesiones!$B$4:$B$903,Parámetros!$B$21)/Parámetros!$D$21) -> 0 | O12: =IF(Parámetros!$D$22=0,0,COUNTIFS(Sesiones!$A$4:$A$903,$A12,Sesiones!$B$4:$B$903,Parámetros!$B$22)/Parámetros!$D$22) -> 0 | P12: =IF(Parámetros!$D$23=0,0,COUNTIFS(Sesiones!$A$4:$A$903,$A12,Sesiones!$B$4:$B$903,Parámetros!$B$23)/Parámetros!$D$23) -> 0 | Q12: =IF(Parámetros!$D$24=0,0,COUNTIFS(Sesiones!$A$4:$A$903,$A12,Sesiones!$B$4:$B$903,Parámetros!$B$24)/Parámetros!$D$24) -> 0 | R12: =IF(Parámetros!$D$25=0,0,COUNTIFS(Sesiones!$A$4:$A$903,$A12,Sesiones!$B$4:$B$903,Parámetros!$B$25)/Parámetros!$D$25) -> 0 | S12: =IF(Parámetros!$D$26=0,0,COUNTIFS(Sesiones!$A$4:$A$903,$A12,Sesiones!$B$4:$B$903,Parámetros!$B$26)/Parámetros!$D$26) -> 0 | T12: =IF(Parámetros!$D$27=0,0,COUNTIFS(Sesiones!$A$4:$A$903,$A12,Sesiones!$B$4:$B$903,Parámetros!$B$27)/Parámetros!$D$27) -> 0
A13: =DATE(Parámetros!$C$6,Parámetros!$C$7,10) -> 46244 | B13: =SUMIFS('Caja Diaria'!$F$4:$F$403,'Caja Diaria'!$B$4:$B$403,"Ingreso",'Caja Diaria'!$A$4:$A$403,$A13) -> 0 | C13: =SUMIFS('Caja Diaria'!$F$4:$F$403,'Caja Diaria'!$B$4:$B$403,"Egreso",'Caja Diaria'!$A$4:$A$403,$A13) -> 0 | D13: =B13-C13 -> 0 | E13: =E12+D13 -> 5761500 | F13: =F12+SUMIFS('Caja Diaria'!$F$4:$F$403,'Caja Diaria'!$B$4:$B$403,"Ingreso",'Caja Diaria'!$E$4:$E$403,"Efectivo",'Caja Diaria'!$A$4:$A$403,$A13)-SUMIFS('Caja Diaria'!$F$4:$F$403,'Caja Diaria'!$B$4:$B$403,"Egreso",'Caja Diaria'!$E$4:$E$403,"Efectivo",'Caja Diaria'!$A$4:$A$403,$A13) -> 468000 | G13: =B13/Parámetros!$C$8 -> 0 | H13: =IF(Parámetros!$D$15=0,0,COUNTIFS(Sesiones!$A$4:$A$903,$A13,Sesiones!$B$4:$B$903,Parámetros!$B$15)/Parámetros!$D$15) -> 0 | I13: =IF(Parámetros!$D$16=0,0,COUNTIFS(Sesiones!$A$4:$A$903,$A13,Sesiones!$B$4:$B$903,Parámetros!$B$16)/Parámetros!$D$16) -> 0 | J13: =IF(Parámetros!$D$17=0,0,COUNTIFS(Sesiones!$A$4:$A$903,$A13,Sesiones!$B$4:$B$903,Parámetros!$B$17)/Parámetros!$D$17) -> 0 | K13: =IF(Parámetros!$D$18=0,0,COUNTIFS(Sesiones!$A$4:$A$903,$A13,Sesiones!$B$4:$B$903,Parámetros!$B$18)/Parámetros!$D$18) -> 0 | L13: =IF(Parámetros!$D$19=0,0,COUNTIFS(Sesiones!$A$4:$A$903,$A13,Sesiones!$B$4:$B$903,Parámetros!$B$19)/Parámetros!$D$19) -> 0 | M13: =IF(Parámetros!$D$20=0,0,COUNTIFS(Sesiones!$A$4:$A$903,$A13,Sesiones!$B$4:$B$903,Parámetros!$B$20)/Parámetros!$D$20) -> 0 | N13: =IF(Parámetros!$D$21=0,0,COUNTIFS(Sesiones!$A$4:$A$903,$A13,Sesiones!$B$4:$B$903,Parámetros!$B$21)/Parámetros!$D$21) -> 0 | O13: =IF(Parámetros!$D$22=0,0,COUNTIFS(Sesiones!$A$4:$A$903,$A13,Sesiones!$B$4:$B$903,Parámetros!$B$22)/Parámetros!$D$22) -> 0 | P13: =IF(Parámetros!$D$23=0,0,COUNTIFS(Sesiones!$A$4:$A$903,$A13,Sesiones!$B$4:$B$903,Parámetros!$B$23)/Parámetros!$D$23) -> 0 | Q13: =IF(Parámetros!$D$24=0,0,COUNTIFS(Sesiones!$A$4:$A$903,$A13,Sesiones!$B$4:$B$903,Parámetros!$B$24)/Parámetros!$D$24) -> 0 | R13: =IF(Parámetros!$D$25=0,0,COUNTIFS(Sesiones!$A$4:$A$903,$A13,Sesiones!$B$4:$B$903,Parámetros!$B$25)/Parámetros!$D$25) -> 0 | S13: =IF(Parámetros!$D$26=0,0,COUNTIFS(Sesiones!$A$4:$A$903,$A13,Sesiones!$B$4:$B$903,Parámetros!$B$26)/Parámetros!$D$26) -> 0 | T13: =IF(Parámetros!$D$27=0,0,COUNTIFS(Sesiones!$A$4:$A$903,$A13,Sesiones!$B$4:$B$903,Parámetros!$B$27)/Parámetros!$D$27) -> 0
A14: =DATE(Parámetros!$C$6,Parámetros!$C$7,11) -> 46245 | B14: =SUMIFS('Caja Diaria'!$F$4:$F$403,'Caja Diaria'!$B$4:$B$403,"Ingreso",'Caja Diaria'!$A$4:$A$403,$A14) -> 0 | C14: =SUMIFS('Caja Diaria'!$F$4:$F$403,'Caja Diaria'!$B$4:$B$403,"Egreso",'Caja Diaria'!$A$4:$A$403,$A14) -> 0 | D14: =B14-C14 -> 0 | E14: =E13+D14 -> 5761500 | F14: =F13+SUMIFS('Caja Diaria'!$F$4:$F$403,'Caja Diaria'!$B$4:$B$403,"Ingreso",'Caja Diaria'!$E$4:$E$403,"Efectivo",'Caja Diaria'!$A$4:$A$403,$A14)-SUMIFS('Caja Diaria'!$F$4:$F$403,'Caja Diaria'!$B$4:$B$403,"Egreso",'Caja Diaria'!$E$4:$E$403,"Efectivo",'Caja Diaria'!$A$4:$A$403,$A14) -> 468000 | G14: =B14/Parámetros!$C$8 -> 0 | H14: =IF(Parámetros!$D$15=0,0,COUNTIFS(Sesiones!$A$4:$A$903,$A14,Sesiones!$B$4:$B$903,Parámetros!$B$15)/Parámetros!$D$15) -> 0 | I14: =IF(Parámetros!$D$16=0,0,COUNTIFS(Sesiones!$A$4:$A$903,$A14,Sesiones!$B$4:$B$903,Parámetros!$B$16)/Parámetros!$D$16) -> 0 | J14: =IF(Parámetros!$D$17=0,0,COUNTIFS(Sesiones!$A$4:$A$903,$A14,Sesiones!$B$4:$B$903,Parámetros!$B$17)/Parámetros!$D$17) -> 0 | K14: =IF(Parámetros!$D$18=0,0,COUNTIFS(Sesiones!$A$4:$A$903,$A14,Sesiones!$B$4:$B$903,Parámetros!$B$18)/Parámetros!$D$18) -> 0 | L14: =IF(Parámetros!$D$19=0,0,COUNTIFS(Sesiones!$A$4:$A$903,$A14,Sesiones!$B$4:$B$903,Parámetros!$B$19)/Parámetros!$D$19) -> 0 | M14: =IF(Parámetros!$D$20=0,0,COUNTIFS(Sesiones!$A$4:$A$903,$A14,Sesiones!$B$4:$B$903,Parámetros!$B$20)/Parámetros!$D$20) -> 0 | N14: =IF(Parámetros!$D$21=0,0,COUNTIFS(Sesiones!$A$4:$A$903,$A14,Sesiones!$B$4:$B$903,Parámetros!$B$21)/Parámetros!$D$21) -> 0 | O14: =IF(Parámetros!$D$22=0,0,COUNTIFS(Sesiones!$A$4:$A$903,$A14,Sesiones!$B$4:$B$903,Parámetros!$B$22)/Parámetros!$D$22) -> 0 | P14: =IF(Parámetros!$D$23=0,0,COUNTIFS(Sesiones!$A$4:$A$903,$A14,Sesiones!$B$4:$B$903,Parámetros!$B$23)/Parámetros!$D$23) -> 0 | Q14: =IF(Parámetros!$D$24=0,0,COUNTIFS(Sesiones!$A$4:$A$903,$A14,Sesiones!$B$4:$B$903,Parámetros!$B$24)/Parámetros!$D$24) -> 0 | R14: =IF(Parámetros!$D$25=0,0,COUNTIFS(Sesiones!$A$4:$A$903,$A14,Sesiones!$B$4:$B$903,Parámetros!$B$25)/Parámetros!$D$25) -> 0 | S14: =IF(Parámetros!$D$26=0,0,COUNTIFS(Sesiones!$A$4:$A$903,$A14,Sesiones!$B$4:$B$903,Parámetros!$B$26)/Parámetros!$D$26) -> 0 | T14: =IF(Parámetros!$D$27=0,0,COUNTIFS(Sesiones!$A$4:$A$903,$A14,Sesiones!$B$4:$B$903,Parámetros!$B$27)/Parámetros!$D$27) -> 0
A15: =DATE(Parámetros!$C$6,Parámetros!$C$7,12) -> 46246 | B15: =SUMIFS('Caja Diaria'!$F$4:$F$403,'Caja Diaria'!$B$4:$B$403,"Ingreso",'Caja Diaria'!$A$4:$A$403,$A15) -> 0 | C15: =SUMIFS('Caja Diaria'!$F$4:$F$403,'Caja Diaria'!$B$4:$B$403,"Egreso",'Caja Diaria'!$A$4:$A$403,$A15) -> 0 | D15: =B15-C15 -> 0 | E15: =E14+D15 -> 5761500 | F15: =F14+SUMIFS('Caja Diaria'!$F$4:$F$403,'Caja Diaria'!$B$4:$B$403,"Ingreso",'Caja Diaria'!$E$4:$E$403,"Efectivo",'Caja Diaria'!$A$4:$A$403,$A15)-SUMIFS('Caja Diaria'!$F$4:$F$403,'Caja Diaria'!$B$4:$B$403,"Egreso",'Caja Diaria'!$E$4:$E$403,"Efectivo",'Caja Diaria'!$A$4:$A$403,$A15) -> 468000 | G15: =B15/Parámetros!$C$8 -> 0 | H15: =IF(Parámetros!$D$15=0,0,COUNTIFS(Sesiones!$A$4:$A$903,$A15,Sesiones!$B$4:$B$903,Parámetros!$B$15)/Parámetros!$D$15) -> 0 | I15: =IF(Parámetros!$D$16=0,0,COUNTIFS(Sesiones!$A$4:$A$903,$A15,Sesiones!$B$4:$B$903,Parámetros!$B$16)/Parámetros!$D$16) -> 0 | J15: =IF(Parámetros!$D$17=0,0,COUNTIFS(Sesiones!$A$4:$A$903,$A15,Sesiones!$B$4:$B$903,Parámetros!$B$17)/Parámetros!$D$17) -> 0 | K15: =IF(Parámetros!$D$18=0,0,COUNTIFS(Sesiones!$A$4:$A$903,$A15,Sesiones!$B$4:$B$903,Parámetros!$B$18)/Parámetros!$D$18) -> 0 | L15: =IF(Parámetros!$D$19=0,0,COUNTIFS(Sesiones!$A$4:$A$903,$A15,Sesiones!$B$4:$B$903,Parámetros!$B$19)/Parámetros!$D$19) -> 0 | M15: =IF(Parámetros!$D$20=0,0,COUNTIFS(Sesiones!$A$4:$A$903,$A15,Sesiones!$B$4:$B$903,Parámetros!$B$20)/Parámetros!$D$20) -> 0 | N15: =IF(Parámetros!$D$21=0,0,COUNTIFS(Sesiones!$A$4:$A$903,$A15,Sesiones!$B$4:$B$903,Parámetros!$B$21)/Parámetros!$D$21) -> 0 | O15: =IF(Parámetros!$D$22=0,0,COUNTIFS(Sesiones!$A$4:$A$903,$A15,Sesiones!$B$4:$B$903,Parámetros!$B$22)/Parámetros!$D$22) -> 0 | P15: =IF(Parámetros!$D$23=0,0,COUNTIFS(Sesiones!$A$4:$A$903,$A15,Sesiones!$B$4:$B$903,Parámetros!$B$23)/Parámetros!$D$23) -> 0 | Q15: =IF(Parámetros!$D$24=0,0,COUNTIFS(Sesiones!$A$4:$A$903,$A15,Sesiones!$B$4:$B$903,Parámetros!$B$24)/Parámetros!$D$24) -> 0 | R15: =IF(Parámetros!$D$25=0,0,COUNTIFS(Sesiones!$A$4:$A$903,$A15,Sesiones!$B$4:$B$903,Parámetros!$B$25)/Parámetros!$D$25) -> 0 | S15: =IF(Parámetros!$D$26=0,0,COUNTIFS(Sesiones!$A$4:$A$903,$A15,Sesiones!$B$4:$B$903,Parámetros!$B$26)/Parámetros!$D$26) -> 0 | T15: =IF(Parámetros!$D$27=0,0,COUNTIFS(Sesiones!$A$4:$A$903,$A15,Sesiones!$B$4:$B$903,Parámetros!$B$27)/Parámetros!$D$27) -> 0
A16: =DATE(Parámetros!$C$6,Parámetros!$C$7,13) -> 46247 | B16: =SUMIFS('Caja Diaria'!$F$4:$F$403,'Caja Diaria'!$B$4:$B$403,"Ingreso",'Caja Diaria'!$A$4:$A$403,$A16) -> 0 | C16: =SUMIFS('Caja Diaria'!$F$4:$F$403,'Caja Diaria'!$B$4:$B$403,"Egreso",'Caja Diaria'!$A$4:$A$403,$A16) -> 0 | D16: =B16-C16 -> 0 | E16: =E15+D16 -> 5761500 | F16: =F15+SUMIFS('Caja Diaria'!$F$4:$F$403,'Caja Diaria'!$B$4:$B$403,"Ingreso",'Caja Diaria'!$E$4:$E$403,"Efectivo",'Caja Diaria'!$A$4:$A$403,$A16)-SUMIFS('Caja Diaria'!$F$4:$F$403,'Caja Diaria'!$B$4:$B$403,"Egreso",'Caja Diaria'!$E$4:$E$403,"Efectivo",'Caja Diaria'!$A$4:$A$403,$A16) -> 468000 | G16: =B16/Parámetros!$C$8 -> 0 | H16: =IF(Parámetros!$D$15=0,0,COUNTIFS(Sesiones!$A$4:$A$903,$A16,Sesiones!$B$4:$B$903,Parámetros!$B$15)/Parámetros!$D$15) -> 0 | I16: =IF(Parámetros!$D$16=0,0,COUNTIFS(Sesiones!$A$4:$A$903,$A16,Sesiones!$B$4:$B$903,Parámetros!$B$16)/Parámetros!$D$16) -> 0 | J16: =IF(Parámetros!$D$17=0,0,COUNTIFS(Sesiones!$A$4:$A$903,$A16,Sesiones!$B$4:$B$903,Parámetros!$B$17)/Parámetros!$D$17) -> 0 | K16: =IF(Parámetros!$D$18=0,0,COUNTIFS(Sesiones!$A$4:$A$903,$A16,Sesiones!$B$4:$B$903,Parámetros!$B$18)/Parámetros!$D$18) -> 0 | L16: =IF(Parámetros!$D$19=0,0,COUNTIFS(Sesiones!$A$4:$A$903,$A16,Sesiones!$B$4:$B$903,Parámetros!$B$19)/Parámetros!$D$19) -> 0 | M16: =IF(Parámetros!$D$20=0,0,COUNTIFS(Sesiones!$A$4:$A$903,$A16,Sesiones!$B$4:$B$903,Parámetros!$B$20)/Parámetros!$D$20) -> 0 | N16: =IF(Parámetros!$D$21=0,0,COUNTIFS(Sesiones!$A$4:$A$903,$A16,Sesiones!$B$4:$B$903,Parámetros!$B$21)/Parámetros!$D$21) -> 0 | O16: =IF(Parámetros!$D$22=0,0,COUNTIFS(Sesiones!$A$4:$A$903,$A16,Sesiones!$B$4:$B$903,Parámetros!$B$22)/Parámetros!$D$22) -> 0 | P16: =IF(Parámetros!$D$23=0,0,COUNTIFS(Sesiones!$A$4:$A$903,$A16,Sesiones!$B$4:$B$903,Parámetros!$B$23)/Parámetros!$D$23) -> 0 | Q16: =IF(Parámetros!$D$24=0,0,COUNTIFS(Sesiones!$A$4:$A$903,$A16,Sesiones!$B$4:$B$903,Parámetros!$B$24)/Parámetros!$D$24) -> 0 | R16: =IF(Parámetros!$D$25=0,0,COUNTIFS(Sesiones!$A$4:$A$903,$A16,Sesiones!$B$4:$B$903,Parámetros!$B$25)/Parámetros!$D$25) -> 0 | S16: =IF(Parámetros!$D$26=0,0,COUNTIFS(Sesiones!$A$4:$A$903,$A16,Sesiones!$B$4:$B$903,Parámetros!$B$26)/Parámetros!$D$26) -> 0 | T16: =IF(Parámetros!$D$27=0,0,COUNTIFS(Sesiones!$A$4:$A$903,$A16,Sesiones!$B$4:$B$903,Parámetros!$B$27)/Parámetros!$D$27) -> 0
A17: =DATE(Parámetros!$C$6,Parámetros!$C$7,14) -> 46248 | B17: =SUMIFS('Caja Diaria'!$F$4:$F$403,'Caja Diaria'!$B$4:$B$403,"Ingreso",'Caja Diaria'!$A$4:$A$403,$A17) -> 0 | C17: =SUMIFS('Caja Diaria'!$F$4:$F$403,'Caja Diaria'!$B$4:$B$403,"Egreso",'Caja Diaria'!$A$4:$A$403,$A17) -> 0 | D17: =B17-C17 -> 0 | E17: =E16+D17 -> 5761500 | F17: =F16+SUMIFS('Caja Diaria'!$F$4:$F$403,'Caja Diaria'!$B$4:$B$403,"Ingreso",'Caja Diaria'!$E$4:$E$403,"Efectivo",'Caja Diaria'!$A$4:$A$403,$A17)-SUMIFS('Caja Diaria'!$F$4:$F$403,'Caja Diaria'!$B$4:$B$403,"Egreso",'Caja Diaria'!$E$4:$E$403,"Efectivo",'Caja Diaria'!$A$4:$A$403,$A17) -> 468000 | G17: =B17/Parámetros!$C$8 -> 0 | H17: =IF(Parámetros!$D$15=0,0,COUNTIFS(Sesiones!$A$4:$A$903,$A17,Sesiones!$B$4:$B$903,Parámetros!$B$15)/Parámetros!$D$15) -> 0 | I17: =IF(Parámetros!$D$16=0,0,COUNTIFS(Sesiones!$A$4:$A$903,$A17,Sesiones!$B$4:$B$903,Parámetros!$B$16)/Parámetros!$D$16) -> 0 | J17: =IF(Parámetros!$D$17=0,0,COUNTIFS(Sesiones!$A$4:$A$903,$A17,Sesiones!$B$4:$B$903,Parámetros!$B$17)/Parámetros!$D$17) -> 0 | K17: =IF(Parámetros!$D$18=0,0,COUNTIFS(Sesiones!$A$4:$A$903,$A17,Sesiones!$B$4:$B$903,Parámetros!$B$18)/Parámetros!$D$18) -> 0 | L17: =IF(Parámetros!$D$19=0,0,COUNTIFS(Sesiones!$A$4:$A$903,$A17,Sesiones!$B$4:$B$903,Parámetros!$B$19)/Parámetros!$D$19) -> 0 | M17: =IF(Parámetros!$D$20=0,0,COUNTIFS(Sesiones!$A$4:$A$903,$A17,Sesiones!$B$4:$B$903,Parámetros!$B$20)/Parámetros!$D$20) -> 0 | N17: =IF(Parámetros!$D$21=0,0,COUNTIFS(Sesiones!$A$4:$A$903,$A17,Sesiones!$B$4:$B$903,Parámetros!$B$21)/Parámetros!$D$21) -> 0 | O17: =IF(Parámetros!$D$22=0,0,COUNTIFS(Sesiones!$A$4:$A$903,$A17,Sesiones!$B$4:$B$903,Parámetros!$B$22)/Parámetros!$D$22) -> 0 | P17: =IF(Parámetros!$D$23=0,0,COUNTIFS(Sesiones!$A$4:$A$903,$A17,Sesiones!$B$4:$B$903,Parámetros!$B$23)/Parámetros!$D$23) -> 0 | Q17: =IF(Parámetros!$D$24=0,0,COUNTIFS(Sesiones!$A$4:$A$903,$A17,Sesiones!$B$4:$B$903,Parámetros!$B$24)/Parámetros!$D$24) -> 0 | R17: =IF(Parámetros!$D$25=0,0,COUNTIFS(Sesiones!$A$4:$A$903,$A17,Sesiones!$B$4:$B$903,Parámetros!$B$25)/Parámetros!$D$25) -> 0 | S17: =IF(Parámetros!$D$26=0,0,COUNTIFS(Sesiones!$A$4:$A$903,$A17,Sesiones!$B$4:$B$903,Parámetros!$B$26)/Parámetros!$D$26) -> 0 | T17: =IF(Parámetros!$D$27=0,0,COUNTIFS(Sesiones!$A$4:$A$903,$A17,Sesiones!$B$4:$B$903,Parámetros!$B$27)/Parámetros!$D$27) -> 0
A18: =DATE(Parámetros!$C$6,Parámetros!$C$7,15) -> 46249 | B18: =SUMIFS('Caja Diaria'!$F$4:$F$403,'Caja Diaria'!$B$4:$B$403,"Ingreso",'Caja Diaria'!$A$4:$A$403,$A18) -> 0 | C18: =SUMIFS('Caja Diaria'!$F$4:$F$403,'Caja Diaria'!$B$4:$B$403,"Egreso",'Caja Diaria'!$A$4:$A$403,$A18) -> 0 | D18: =B18-C18 -> 0 | E18: =E17+D18 -> 5761500 | F18: =F17+SUMIFS('Caja Diaria'!$F$4:$F$403,'Caja Diaria'!$B$4:$B$403,"Ingreso",'Caja Diaria'!$E$4:$E$403,"Efectivo",'Caja Diaria'!$A$4:$A$403,$A18)-SUMIFS('Caja Diaria'!$F$4:$F$403,'Caja Diaria'!$B$4:$B$403,"Egreso",'Caja Diaria'!$E$4:$E$403,"Efectivo",'Caja Diaria'!$A$4:$A$403,$A18) -> 468000 | G18: =B18/Parámetros!$C$8 -> 0 | H18: =IF(Parámetros!$D$15=0,0,COUNTIFS(Sesiones!$A$4:$A$903,$A18,Sesiones!$B$4:$B$903,Parámetros!$B$15)/Parámetros!$D$15) -> 0 | I18: =IF(Parámetros!$D$16=0,0,COUNTIFS(Sesiones!$A$4:$A$903,$A18,Sesiones!$B$4:$B$903,Parámetros!$B$16)/Parámetros!$D$16) -> 0 | J18: =IF(Parámetros!$D$17=0,0,COUNTIFS(Sesiones!$A$4:$A$903,$A18,Sesiones!$B$4:$B$903,Parámetros!$B$17)/Parámetros!$D$17) -> 0 | K18: =IF(Parámetros!$D$18=0,0,COUNTIFS(Sesiones!$A$4:$A$903,$A18,Sesiones!$B$4:$B$903,Parámetros!$B$18)/Parámetros!$D$18) -> 0 | L18: =IF(Parámetros!$D$19=0,0,COUNTIFS(Sesiones!$A$4:$A$903,$A18,Sesiones!$B$4:$B$903,Parámetros!$B$19)/Parámetros!$D$19) -> 0 | M18: =IF(Parámetros!$D$20=0,0,COUNTIFS(Sesiones!$A$4:$A$903,$A18,Sesiones!$B$4:$B$903,Parámetros!$B$20)/Parámetros!$D$20) -> 0 | N18: =IF(Parámetros!$D$21=0,0,COUNTIFS(Sesiones!$A$4:$A$903,$A18,Sesiones!$B$4:$B$903,Parámetros!$B$21)/Parámetros!$D$21) -> 0 | O18: =IF(Parámetros!$D$22=0,0,COUNTIFS(Sesiones!$A$4:$A$903,$A18,Sesiones!$B$4:$B$903,Parámetros!$B$22)/Parámetros!$D$22) -> 0 | P18: =IF(Parámetros!$D$23=0,0,COUNTIFS(Sesiones!$A$4:$A$903,$A18,Sesiones!$B$4:$B$903,Parámetros!$B$23)/Parámetros!$D$23) -> 0 | Q18: =IF(Parámetros!$D$24=0,0,COUNTIFS(Sesiones!$A$4:$A$903,$A18,Sesiones!$B$4:$B$903,Parámetros!$B$24)/Parámetros!$D$24) -> 0 | R18: =IF(Parámetros!$D$25=0,0,COUNTIFS(Sesiones!$A$4:$A$903,$A18,Sesiones!$B$4:$B$903,Parámetros!$B$25)/Parámetros!$D$25) -> 0 | S18: =IF(Parámetros!$D$26=0,0,COUNTIFS(Sesiones!$A$4:$A$903,$A18,Sesiones!$B$4:$B$903,Parámetros!$B$26)/Parámetros!$D$26) -> 0 | T18: =IF(Parámetros!$D$27=0,0,COUNTIFS(Sesiones!$A$4:$A$903,$A18,Sesiones!$B$4:$B$903,Parámetros!$B$27)/Parámetros!$D$27) -> 0
A19: =DATE(Parámetros!$C$6,Parámetros!$C$7,16) -> 46250 | B19: =SUMIFS('Caja Diaria'!$F$4:$F$403,'Caja Diaria'!$B$4:$B$403,"Ingreso",'Caja Diaria'!$A$4:$A$403,$A19) -> 0 | C19: =SUMIFS('Caja Diaria'!$F$4:$F$403,'Caja Diaria'!$B$4:$B$403,"Egreso",'Caja Diaria'!$A$4:$A$403,$A19) -> 0 | D19: =B19-C19 -> 0 | E19: =E18+D19 -> 5761500 | F19: =F18+SUMIFS('Caja Diaria'!$F$4:$F$403,'Caja Diaria'!$B$4:$B$403,"Ingreso",'Caja Diaria'!$E$4:$E$403,"Efectivo",'Caja Diaria'!$A$4:$A$403,$A19)-SUMIFS('Caja Diaria'!$F$4:$F$403,'Caja Diaria'!$B$4:$B$403,"Egreso",'Caja Diaria'!$E$4:$E$403,"Efectivo",'Caja Diaria'!$A$4:$A$403,$A19) -> 468000 | G19: =B19/Parámetros!$C$8 -> 0 | H19: =IF(Parámetros!$D$15=0,0,COUNTIFS(Sesiones!$A$4:$A$903,$A19,Sesiones!$B$4:$B$903,Parámetros!$B$15)/Parámetros!$D$15) -> 0 | I19: =IF(Parámetros!$D$16=0,0,COUNTIFS(Sesiones!$A$4:$A$903,$A19,Sesiones!$B$4:$B$903,Parámetros!$B$16)/Parámetros!$D$16) -> 0 | J19: =IF(Parámetros!$D$17=0,0,COUNTIFS(Sesiones!$A$4:$A$903,$A19,Sesiones!$B$4:$B$903,Parámetros!$B$17)/Parámetros!$D$17) -> 0 | K19: =IF(Parámetros!$D$18=0,0,COUNTIFS(Sesiones!$A$4:$A$903,$A19,Sesiones!$B$4:$B$903,Parámetros!$B$18)/Parámetros!$D$18) -> 0 | L19: =IF(Parámetros!$D$19=0,0,COUNTIFS(Sesiones!$A$4:$A$903,$A19,Sesiones!$B$4:$B$903,Parámetros!$B$19)/Parámetros!$D$19) -> 0 | M19: =IF(Parámetros!$D$20=0,0,COUNTIFS(Sesiones!$A$4:$A$903,$A19,Sesiones!$B$4:$B$903,Parámetros!$B$20)/Parámetros!$D$20) -> 0 | N19: =IF(Parámetros!$D$21=0,0,COUNTIFS(Sesiones!$A$4:$A$903,$A19,Sesiones!$B$4:$B$903,Parámetros!$B$21)/Parámetros!$D$21) -> 0 | O19: =IF(Parámetros!$D$22=0,0,COUNTIFS(Sesiones!$A$4:$A$903,$A19,Sesiones!$B$4:$B$903,Parámetros!$B$22)/Parámetros!$D$22) -> 0 | P19: =IF(Parámetros!$D$23=0,0,COUNTIFS(Sesiones!$A$4:$A$903,$A19,Sesiones!$B$4:$B$903,Parámetros!$B$23)/Parámetros!$D$23) -> 0 | Q19: =IF(Parámetros!$D$24=0,0,COUNTIFS(Sesiones!$A$4:$A$903,$A19,Sesiones!$B$4:$B$903,Parámetros!$B$24)/Parámetros!$D$24) -> 0 | R19: =IF(Parámetros!$D$25=0,0,COUNTIFS(Sesiones!$A$4:$A$903,$A19,Sesiones!$B$4:$B$903,Parámetros!$B$25)/Parámetros!$D$25) -> 0 | S19: =IF(Parámetros!$D$26=0,0,COUNTIFS(Sesiones!$A$4:$A$903,$A19,Sesiones!$B$4:$B$903,Parámetros!$B$26)/Parámetros!$D$26) -> 0 | T19: =IF(Parámetros!$D$27=0,0,COUNTIFS(Sesiones!$A$4:$A$903,$A19,Sesiones!$B$4:$B$903,Parámetros!$B$27)/Parámetros!$D$27) -> 0
A20: =DATE(Parámetros!$C$6,Parámetros!$C$7,17) -> 46251 | B20: =SUMIFS('Caja Diaria'!$F$4:$F$403,'Caja Diaria'!$B$4:$B$403,"Ingreso",'Caja Diaria'!$A$4:$A$403,$A20) -> 0 | C20: =SUMIFS('Caja Diaria'!$F$4:$F$403,'Caja Diaria'!$B$4:$B$403,"Egreso",'Caja Diaria'!$A$4:$A$403,$A20) -> 0 | D20: =B20-C20 -> 0 | E20: =E19+D20 -> 5761500 | F20: =F19+SUMIFS('Caja Diaria'!$F$4:$F$403,'Caja Diaria'!$B$4:$B$403,"Ingreso",'Caja Diaria'!$E$4:$E$403,"Efectivo",'Caja Diaria'!$A$4:$A$403,$A20)-SUMIFS('Caja Diaria'!$F$4:$F$403,'Caja Diaria'!$B$4:$B$403,"Egreso",'Caja Diaria'!$E$4:$E$403,"Efectivo",'Caja Diaria'!$A$4:$A$403,$A20) -> 468000 | G20: =B20/Parámetros!$C$8 -> 0 | H20: =IF(Parámetros!$D$15=0,0,COUNTIFS(Sesiones!$A$4:$A$903,$A20,Sesiones!$B$4:$B$903,Parámetros!$B$15)/Parámetros!$D$15) -> 0 | I20: =IF(Parámetros!$D$16=0,0,COUNTIFS(Sesiones!$A$4:$A$903,$A20,Sesiones!$B$4:$B$903,Parámetros!$B$16)/Parámetros!$D$16) -> 0 | J20: =IF(Parámetros!$D$17=0,0,COUNTIFS(Sesiones!$A$4:$A$903,$A20,Sesiones!$B$4:$B$903,Parámetros!$B$17)/Parámetros!$D$17) -> 0 | K20: =IF(Parámetros!$D$18=0,0,COUNTIFS(Sesiones!$A$4:$A$903,$A20,Sesiones!$B$4:$B$903,Parámetros!$B$18)/Parámetros!$D$18) -> 0 | L20: =IF(Parámetros!$D$19=0,0,COUNTIFS(Sesiones!$A$4:$A$903,$A20,Sesiones!$B$4:$B$903,Parámetros!$B$19)/Parámetros!$D$19) -> 0 | M20: =IF(Parámetros!$D$20=0,0,COUNTIFS(Sesiones!$A$4:$A$903,$A20,Sesiones!$B$4:$B$903,Parámetros!$B$20)/Parámetros!$D$20) -> 0 | N20: =IF(Parámetros!$D$21=0,0,COUNTIFS(Sesiones!$A$4:$A$903,$A20,Sesiones!$B$4:$B$903,Parámetros!$B$21)/Parámetros!$D$21) -> 0 | O20: =IF(Parámetros!$D$22=0,0,COUNTIFS(Sesiones!$A$4:$A$903,$A20,Sesiones!$B$4:$B$903,Parámetros!$B$22)/Parámetros!$D$22) -> 0 | P20: =IF(Parámetros!$D$23=0,0,COUNTIFS(Sesiones!$A$4:$A$903,$A20,Sesiones!$B$4:$B$903,Parámetros!$B$23)/Parámetros!$D$23) -> 0 | Q20: =IF(Parámetros!$D$24=0,0,COUNTIFS(Sesiones!$A$4:$A$903,$A20,Sesiones!$B$4:$B$903,Parámetros!$B$24)/Parámetros!$D$24) -> 0 | R20: =IF(Parámetros!$D$25=0,0,COUNTIFS(Sesiones!$A$4:$A$903,$A20,Sesiones!$B$4:$B$903,Parámetros!$B$25)/Parámetros!$D$25) -> 0 | S20: =IF(Parámetros!$D$26=0,0,COUNTIFS(Sesiones!$A$4:$A$903,$A20,Sesiones!$B$4:$B$903,Parámetros!$B$26)/Parámetros!$D$26) -> 0 | T20: =IF(Parámetros!$D$27=0,0,COUNTIFS(Sesiones!$A$4:$A$903,$A20,Sesiones!$B$4:$B$903,Parámetros!$B$27)/Parámetros!$D$27) -> 0
A21: =DATE(Parámetros!$C$6,Parámetros!$C$7,18) -> 46252 | B21: =SUMIFS('Caja Diaria'!$F$4:$F$403,'Caja Diaria'!$B$4:$B$403,"Ingreso",'Caja Diaria'!$A$4:$A$403,$A21) -> 0 | C21: =SUMIFS('Caja Diaria'!$F$4:$F$403,'Caja Diaria'!$B$4:$B$403,"Egreso",'Caja Diaria'!$A$4:$A$403,$A21) -> 0 | D21: =B21-C21 -> 0 | E21: =E20+D21 -> 5761500 | F21: =F20+SUMIFS('Caja Diaria'!$F$4:$F$403,'Caja Diaria'!$B$4:$B$403,"Ingreso",'Caja Diaria'!$E$4:$E$403,"Efectivo",'Caja Diaria'!$A$4:$A$403,$A21)-SUMIFS('Caja Diaria'!$F$4:$F$403,'Caja Diaria'!$B$4:$B$403,"Egreso",'Caja Diaria'!$E$4:$E$403,"Efectivo",'Caja Diaria'!$A$4:$A$403,$A21) -> 468000 | G21: =B21/Parámetros!$C$8 -> 0 | H21: =IF(Parámetros!$D$15=0,0,COUNTIFS(Sesiones!$A$4:$A$903,$A21,Sesiones!$B$4:$B$903,Parámetros!$B$15)/Parámetros!$D$15) -> 0 | I21: =IF(Parámetros!$D$16=0,0,COUNTIFS(Sesiones!$A$4:$A$903,$A21,Sesiones!$B$4:$B$903,Parámetros!$B$16)/Parámetros!$D$16) -> 0 | J21: =IF(Parámetros!$D$17=0,0,COUNTIFS(Sesiones!$A$4:$A$903,$A21,Sesiones!$B$4:$B$903,Parámetros!$B$17)/Parámetros!$D$17) -> 0 | K21: =IF(Parámetros!$D$18=0,0,COUNTIFS(Sesiones!$A$4:$A$903,$A21,Sesiones!$B$4:$B$903,Parámetros!$B$18)/Parámetros!$D$18) -> 0 | L21: =IF(Parámetros!$D$19=0,0,COUNTIFS(Sesiones!$A$4:$A$903,$A21,Sesiones!$B$4:$B$903,Parámetros!$B$19)/Parámetros!$D$19) -> 0 | M21: =IF(Parámetros!$D$20=0,0,COUNTIFS(Sesiones!$A$4:$A$903,$A21,Sesiones!$B$4:$B$903,Parámetros!$B$20)/Parámetros!$D$20) -> 0 | N21: =IF(Parámetros!$D$21=0,0,COUNTIFS(Sesiones!$A$4:$A$903,$A21,Sesiones!$B$4:$B$903,Parámetros!$B$21)/Parámetros!$D$21) -> 0 | O21: =IF(Parámetros!$D$22=0,0,COUNTIFS(Sesiones!$A$4:$A$903,$A21,Sesiones!$B$4:$B$903,Parámetros!$B$22)/Parámetros!$D$22) -> 0 | P21: =IF(Parámetros!$D$23=0,0,COUNTIFS(Sesiones!$A$4:$A$903,$A21,Sesiones!$B$4:$B$903,Parámetros!$B$23)/Parámetros!$D$23) -> 0 | Q21: =IF(Parámetros!$D$24=0,0,COUNTIFS(Sesiones!$A$4:$A$903,$A21,Sesiones!$B$4:$B$903,Parámetros!$B$24)/Parámetros!$D$24) -> 0 | R21: =IF(Parámetros!$D$25=0,0,COUNTIFS(Sesiones!$A$4:$A$903,$A21,Sesiones!$B$4:$B$903,Parámetros!$B$25)/Parámetros!$D$25) -> 0 | S21: =IF(Parámetros!$D$26=0,0,COUNTIFS(Sesiones!$A$4:$A$903,$A21,Sesiones!$B$4:$B$903,Parámetros!$B$26)/Parámetros!$D$26) -> 0 | T21: =IF(Parámetros!$D$27=0,0,COUNTIFS(Sesiones!$A$4:$A$903,$A21,Sesiones!$B$4:$B$903,Parámetros!$B$27)/Parámetros!$D$27) -> 0
A22: =DATE(Parámetros!$C$6,Parámetros!$C$7,19) -> 46253 | B22: =SUMIFS('Caja Diaria'!$F$4:$F$403,'Caja Diaria'!$B$4:$B$403,"Ingreso",'Caja Diaria'!$A$4:$A$403,$A22) -> 0 | C22: =SUMIFS('Caja Diaria'!$F$4:$F$403,'Caja Diaria'!$B$4:$B$403,"Egreso",'Caja Diaria'!$A$4:$A$403,$A22) -> 0 | D22: =B22-C22 -> 0 | E22: =E21+D22 -> 5761500 | F22: =F21+SUMIFS('Caja Diaria'!$F$4:$F$403,'Caja Diaria'!$B$4:$B$403,"Ingreso",'Caja Diaria'!$E$4:$E$403,"Efectivo",'Caja Diaria'!$A$4:$A$403,$A22)-SUMIFS('Caja Diaria'!$F$4:$F$403,'Caja Diaria'!$B$4:$B$403,"Egreso",'Caja Diaria'!$E$4:$E$403,"Efectivo",'Caja Diaria'!$A$4:$A$403,$A22) -> 468000 | G22: =B22/Parámetros!$C$8 -> 0 | H22: =IF(Parámetros!$D$15=0,0,COUNTIFS(Sesiones!$A$4:$A$903,$A22,Sesiones!$B$4:$B$903,Parámetros!$B$15)/Parámetros!$D$15) -> 0 | I22: =IF(Parámetros!$D$16=0,0,COUNTIFS(Sesiones!$A$4:$A$903,$A22,Sesiones!$B$4:$B$903,Parámetros!$B$16)/Parámetros!$D$16) -> 0 | J22: =IF(Parámetros!$D$17=0,0,COUNTIFS(Sesiones!$A$4:$A$903,$A22,Sesiones!$B$4:$B$903,Parámetros!$B$17)/Parámetros!$D$17) -> 0 | K22: =IF(Parámetros!$D$18=0,0,COUNTIFS(Sesiones!$A$4:$A$903,$A22,Sesiones!$B$4:$B$903,Parámetros!$B$18)/Parámetros!$D$18) -> 0 | L22: =IF(Parámetros!$D$19=0,0,COUNTIFS(Sesiones!$A$4:$A$903,$A22,Sesiones!$B$4:$B$903,Parámetros!$B$19)/Parámetros!$D$19) -> 0 | M22: =IF(Parámetros!$D$20=0,0,COUNTIFS(Sesiones!$A$4:$A$903,$A22,Sesiones!$B$4:$B$903,Parámetros!$B$20)/Parámetros!$D$20) -> 0 | N22: =IF(Parámetros!$D$21=0,0,COUNTIFS(Sesiones!$A$4:$A$903,$A22,Sesiones!$B$4:$B$903,Parámetros!$B$21)/Parámetros!$D$21) -> 0 | O22: =IF(Parámetros!$D$22=0,0,COUNTIFS(Sesiones!$A$4:$A$903,$A22,Sesiones!$B$4:$B$903,Parámetros!$B$22)/Parámetros!$D$22) -> 0 | P22: =IF(Parámetros!$D$23=0,0,COUNTIFS(Sesiones!$A$4:$A$903,$A22,Sesiones!$B$4:$B$903,Parámetros!$B$23)/Parámetros!$D$23) -> 0 | Q22: =IF(Parámetros!$D$24=0,0,COUNTIFS(Sesiones!$A$4:$A$903,$A22,Sesiones!$B$4:$B$903,Parámetros!$B$24)/Parámetros!$D$24) -> 0 | R22: =IF(Parámetros!$D$25=0,0,COUNTIFS(Sesiones!$A$4:$A$903,$A22,Sesiones!$B$4:$B$903,Parámetros!$B$25)/Parámetros!$D$25) -> 0 | S22: =IF(Parámetros!$D$26=0,0,COUNTIFS(Sesiones!$A$4:$A$903,$A22,Sesiones!$B$4:$B$903,Parámetros!$B$26)/Parámetros!$D$26) -> 0 | T22: =IF(Parámetros!$D$27=0,0,COUNTIFS(Sesiones!$A$4:$A$903,$A22,Sesiones!$B$4:$B$903,Parámetros!$B$27)/Parámetros!$D$27) -> 0
A23: =DATE(Parámetros!$C$6,Parámetros!$C$7,20) -> 46254 | B23: =SUMIFS('Caja Diaria'!$F$4:$F$403,'Caja Diaria'!$B$4:$B$403,"Ingreso",'Caja Diaria'!$A$4:$A$403,$A23) -> 0 | C23: =SUMIFS('Caja Diaria'!$F$4:$F$403,'Caja Diaria'!$B$4:$B$403,"Egreso",'Caja Diaria'!$A$4:$A$403,$A23) -> 0 | D23: =B23-C23 -> 0 | E23: =E22+D23 -> 5761500 | F23: =F22+SUMIFS('Caja Diaria'!$F$4:$F$403,'Caja Diaria'!$B$4:$B$403,"Ingreso",'Caja Diaria'!$E$4:$E$403,"Efectivo",'Caja Diaria'!$A$4:$A$403,$A23)-SUMIFS('Caja Diaria'!$F$4:$F$403,'Caja Diaria'!$B$4:$B$403,"Egreso",'Caja Diaria'!$E$4:$E$403,"Efectivo",'Caja Diaria'!$A$4:$A$403,$A23) -> 468000 | G23: =B23/Parámetros!$C$8 -> 0 | H23: =IF(Parámetros!$D$15=0,0,COUNTIFS(Sesiones!$A$4:$A$903,$A23,Sesiones!$B$4:$B$903,Parámetros!$B$15)/Parámetros!$D$15) -> 0 | I23: =IF(Parámetros!$D$16=0,0,COUNTIFS(Sesiones!$A$4:$A$903,$A23,Sesiones!$B$4:$B$903,Parámetros!$B$16)/Parámetros!$D$16) -> 0 | J23: =IF(Parámetros!$D$17=0,0,COUNTIFS(Sesiones!$A$4:$A$903,$A23,Sesiones!$B$4:$B$903,Parámetros!$B$17)/Parámetros!$D$17) -> 0 | K23: =IF(Parámetros!$D$18=0,0,COUNTIFS(Sesiones!$A$4:$A$903,$A23,Sesiones!$B$4:$B$903,Parámetros!$B$18)/Parámetros!$D$18) -> 0 | L23: =IF(Parámetros!$D$19=0,0,COUNTIFS(Sesiones!$A$4:$A$903,$A23,Sesiones!$B$4:$B$903,Parámetros!$B$19)/Parámetros!$D$19) -> 0 | M23: =IF(Parámetros!$D$20=0,0,COUNTIFS(Sesiones!$A$4:$A$903,$A23,Sesiones!$B$4:$B$903,Parámetros!$B$20)/Parámetros!$D$20) -> 0 | N23: =IF(Parámetros!$D$21=0,0,COUNTIFS(Sesiones!$A$4:$A$903,$A23,Sesiones!$B$4:$B$903,Parámetros!$B$21)/Parámetros!$D$21) -> 0 | O23: =IF(Parámetros!$D$22=0,0,COUNTIFS(Sesiones!$A$4:$A$903,$A23,Sesiones!$B$4:$B$903,Parámetros!$B$22)/Parámetros!$D$22) -> 0 | P23: =IF(Parámetros!$D$23=0,0,COUNTIFS(Sesiones!$A$4:$A$903,$A23,Sesiones!$B$4:$B$903,Parámetros!$B$23)/Parámetros!$D$23) -> 0 | Q23: =IF(Parámetros!$D$24=0,0,COUNTIFS(Sesiones!$A$4:$A$903,$A23,Sesiones!$B$4:$B$903,Parámetros!$B$24)/Parámetros!$D$24) -> 0 | R23: =IF(Parámetros!$D$25=0,0,COUNTIFS(Sesiones!$A$4:$A$903,$A23,Sesiones!$B$4:$B$903,Parámetros!$B$25)/Parámetros!$D$25) -> 0 | S23: =IF(Parámetros!$D$26=0,0,COUNTIFS(Sesiones!$A$4:$A$903,$A23,Sesiones!$B$4:$B$903,Parámetros!$B$26)/Parámetros!$D$26) -> 0 | T23: =IF(Parámetros!$D$27=0,0,COUNTIFS(Sesiones!$A$4:$A$903,$A23,Sesiones!$B$4:$B$903,Parámetros!$B$27)/Parámetros!$D$27) -> 0
